File: Data/Figure3/230920_A_0.2_gonio.csv
[Measurement conditions]
Sample identification,
Comment - 1,"Configuration=Chi-Phi-Z stage 240 mm (reflection), Owner=User-1, Creation date=10/23/2015 4:48:55 PM"
Comment - 2,"Goniometer=Theta/Theta; Minimum step size 2Theta:0.0001; Minimum step size Omega:0.0001"
Comment - 3,"Sample stage=Chi-Phi-z stage 240 mm (reflection); Minimum step size Phi:0.01; Minimum step size Chi:0.01; Minimum step size Z:0.001"
Comment - 4,"Diffractometer system=EMPYREAN"
Comment - 5,"Measurement program=C:\PANalytical\Data Collector\Programs\Yuki gonio-10-70-3.5min.xrdmp, Identifier={4DE38C63-18BA-4A8A-8B29-657A2F10461B}"
Comment - 6,"Fine Calibration Offset for 2Theta = 0.0141 deg"
Comment - 7,"Fine Calibration Offset for Omega = 0.2992 deg"
Anode material,Cu
K-Alpha1 wavelength,1.5405980
K-Alpha2 wavelength,1.5444260
Ratio K-Alpha2/K-Alpha1,0.500
Divergence slit,Fixed,0.19mm
Monochromator used,NO
Generator voltage, 45
Tube current, 40
File date and time,26/Sep/2023 12:03
Unit cell,
h k l, 0 0 0
Scan axis,Gonio
Scan range,9.999999999,69.992261551
Scan step size,0.0131303
No. of points, 4569
Scan type,CONTINUOUS
Phi,0.00
Psi,0.00
Z,9.265
Time per step,8.670
[Scan points]
Angle, TimePerStep, Intensity
10.006565140, 8.670, 41.0
10.059086271, 8.670, 55.0
10.111607401, 8.670, 48.0
10.164128532, 8.670, 38.0
10.216649663, 8.670, 43.0
10.269170794, 8.670, 48.0
10.321691924, 8.670, 51.0
10.374213055, 8.670, 51.0
10.426734186, 8.670, 45.0
10.479255316, 8.670, 44.0
10.531776447, 8.670, 54.0
10.584297578, 8.670, 47.0
10.636818709, 8.670, 42.0
10.689339839, 8.670, 50.0
10.741860970, 8.670, 46.0
10.794382101, 8.670, 48.0
10.846903231, 8.670, 50.0
10.899424362, 8.670, 48.0
10.951945493, 8.670, 52.0
11.004466623, 8.670, 59.0
11.056987754, 8.670, 42.0
11.109508885, 8.670, 47.0
11.162030016, 8.670, 46.0
11.214551146, 8.670, 36.0
11.267072277, 8.670, 45.0
11.319593408, 8.670, 57.0
11.372114538, 8.670, 53.0
11.424635669, 8.670, 43.0
11.477156800, 8.670, 46.0
11.529677931, 8.670, 34.0
11.582199061, 8.670, 56.0
11.634720192, 8.670, 61.0
11.687241323, 8.670, 54.0
11.739762453, 8.670, 50.0
11.792283584, 8.670, 51.0
11.844804715, 8.670, 40.0
11.897325846, 8.670, 43.0
11.949846976, 8.670, 34.0
12.002368107, 8.670, 53.0
12.054889238, 8.670, 60.0
12.107410368, 8.670, 58.0
12.159931499, 8.670, 45.0
12.212452630, 8.670, 52.0
12.264973760, 8.670, 42.0
12.317494891, 8.670, 40.0
12.370016022, 8.670, 48.0
12.422537153, 8.670, 80.0
12.475058283, 8.670, 51.0
12.527579414, 8.670, 50.0
12.580100545, 8.670, 49.0
12.632621675, 8.670, 58.0
12.685142806, 8.670, 48.0
12.737663937, 8.670, 39.0
12.790185068, 8.670, 42.0
12.842706198, 8.670, 48.0
12.895227329, 8.670, 57.0
12.947748460, 8.670, 54.0
13.000269590, 8.670, 57.0
13.052790721, 8.670, 51.0
13.105311852, 8.670, 34.0
13.157832983, 8.670, 52.0
13.210354113, 8.670, 58.0
13.262875244, 8.670, 77.0
13.315396375, 8.670, 72.0
13.367917505, 8.670, 212.0
13.420438636, 8.670, 433.0
13.472959767, 8.670, 838.0
13.525480898, 8.670, 259.0
13.578002028, 8.670, 152.0
13.630523159, 8.670, 167.0
13.683044290, 8.670, 121.0
13.735565420, 8.670, 142.0
13.788086551, 8.670, 151.0
13.840607682, 8.670, 161.0
13.893128812, 8.670, 159.0
13.945649943, 8.670, 172.0
13.998171074, 8.670, 178.0
14.050692205, 8.670, 163.0
14.103213335, 8.670, 226.0
14.155734466, 8.670, 263.0
14.208255597, 8.670, 404.0
14.260776727, 8.670, 605.0
14.313297858, 8.670, 3631.0
14.365818989, 8.670, 840.0
14.418340120, 8.670, 2053.0
14.470861250, 8.670, 1447.0
14.523382381, 8.670, 1724.0
14.575903512, 8.670, 2108.0
14.628424642, 8.670, 2622.0
14.680945773, 8.670, 3176.0
14.733466904, 8.670, 3773.0
14.785988035, 8.670, 5061.0
14.838509165, 8.670, 9140.0
14.891030296, 8.670, 33044.0
14.943551427, 8.670, 1193666.0
14.996072557, 8.670, 100442.0
15.048593688, 8.670, 7921.0
15.101114819, 8.670, 3025.0
15.153635950, 8.670, 1779.0
15.206157080, 8.670, 1062.0
15.258678211, 8.670, 758.0
15.311199342, 8.670, 570.0
15.363720472, 8.670, 459.0
15.416241603, 8.670, 409.0
15.468762734, 8.670, 292.0
15.521283864, 8.670, 236.0
15.573804995, 8.670, 214.0
15.626326126, 8.670, 206.0
15.678847257, 8.670, 229.0
15.731368387, 8.670, 190.0
15.783889518, 8.670, 153.0
15.836410649, 8.670, 134.0
15.888931779, 8.670, 131.0
15.941452910, 8.670, 120.0
15.993974041, 8.670, 98.0
16.046495172, 8.670, 107.0
16.099016302, 8.670, 103.0
16.151537433, 8.670, 92.0
16.204058564, 8.670, 91.0
16.256579694, 8.670, 93.0
16.309100825, 8.670, 82.0
16.361621956, 8.670, 77.0
16.414143087, 8.670, 74.0
16.466664217, 8.670, 66.0
16.519185348, 8.670, 66.0
16.571706479, 8.670, 57.0
16.624227609, 8.670, 61.0
16.676748740, 8.670, 67.0
16.729269871, 8.670, 55.0
16.781791001, 8.670, 47.0
16.834312132, 8.670, 60.0
16.886833263, 8.670, 60.0
16.939354394, 8.670, 47.0
16.991875524, 8.670, 40.0
17.044396655, 8.670, 46.0
17.096917786, 8.670, 37.0
17.149438916, 8.670, 48.0
17.201960047, 8.670, 41.0
17.254481178, 8.670, 38.0
17.307002309, 8.670, 49.0
17.359523439, 8.670, 49.0
17.412044570, 8.670, 40.0
17.464565701, 8.670, 43.0
17.517086831, 8.670, 41.0
17.569607962, 8.670, 47.0
17.622129093, 8.670, 43.0
17.674650224, 8.670, 33.0
17.727171354, 8.670, 38.0
17.779692485, 8.670, 35.0
17.832213616, 8.670, 30.0
17.884734746, 8.670, 37.0
17.937255877, 8.670, 35.0
17.989777008, 8.670, 33.0
18.042298139, 8.670, 35.0
18.094819269, 8.670, 36.0
18.147340400, 8.670, 31.0
18.199861531, 8.670, 37.0
18.252382661, 8.670, 27.0
18.304903792, 8.670, 30.0
18.357424923, 8.670, 22.0
18.409946053, 8.670, 23.0
18.462467184, 8.670, 29.0
18.514988315, 8.670, 40.0
18.567509446, 8.670, 29.0
18.620030576, 8.670, 29.0
18.672551707, 8.670, 28.0
18.725072838, 8.670, 36.0
18.777593968, 8.670, 37.0
18.830115099, 8.670, 28.0
18.882636230, 8.670, 25.0
18.935157361, 8.670, 25.0
18.987678491, 8.670, 41.0
19.040199622, 8.670, 22.0
19.092720753, 8.670, 35.0
19.145241883, 8.670, 37.0
19.197763014, 8.670, 25.0
19.250284145, 8.670, 26.0
19.302805276, 8.670, 28.0
19.355326406, 8.670, 34.0
19.407847537, 8.670, 24.0
19.460368668, 8.670, 35.0
19.512889798, 8.670, 30.0
19.565410929, 8.670, 38.0
19.617932060, 8.670, 29.0
19.670453191, 8.670, 32.0
19.722974321, 8.670, 19.0
19.775495452, 8.670, 26.0
19.828016583, 8.670, 29.0
19.880537713, 8.670, 35.0
19.933058844, 8.670, 23.0
19.985579975, 8.670, 22.0
20.038101105, 8.670, 25.0
20.090622236, 8.670, 35.0
20.143143367, 8.670, 34.0
20.195664498, 8.670, 37.0
20.248185628, 8.670, 20.0
20.300706759, 8.670, 24.0
20.353227890, 8.670, 30.0
20.405749020, 8.670, 43.0
20.458270151, 8.670, 32.0
20.510791282, 8.670, 23.0
20.563312413, 8.670, 27.0
20.615833543, 8.670, 23.0
20.668354674, 8.670, 28.0
20.720875805, 8.670, 27.0
20.773396935, 8.670, 23.0
20.825918066, 8.670, 28.0
20.878439197, 8.670, 29.0
20.930960328, 8.670, 30.0
20.983481458, 8.670, 22.0
21.036002589, 8.670, 23.0
21.088523720, 8.670, 31.0
21.141044850, 8.670, 31.0
21.193565981, 8.670, 27.0
21.246087112, 8.670, 19.0
21.298608242, 8.670, 29.0
21.351129373, 8.670, 24.0
21.403650504, 8.670, 25.0
21.456171635, 8.670, 31.0
21.508692765, 8.670, 25.0
21.561213896, 8.670, 23.0
21.613735027, 8.670, 16.0
21.666256157, 8.670, 24.0
21.718777288, 8.670, 27.0
21.771298419, 8.670, 23.0
21.823819550, 8.670, 21.0
21.876340680, 8.670, 26.0
21.928861811, 8.670, 28.0
21.981382942, 8.670, 23.0
22.033904072, 8.670, 29.0
22.086425203, 8.670, 28.0
22.138946334, 8.670, 18.0
22.191467465, 8.670, 26.0
22.243988595, 8.670, 21.0
22.296509726, 8.670, 28.0
22.349030857, 8.670, 25.0
22.401551987, 8.670, 22.0
22.454073118, 8.670, 18.0
22.506594249, 8.670, 19.0
22.559115380, 8.670, 17.0
22.611636510, 8.670, 23.0
22.664157641, 8.670, 14.0
22.716678772, 8.670, 21.0
22.769199902, 8.670, 15.0
22.821721033, 8.670, 17.0
22.874242164, 8.670, 26.0
22.926763294, 8.670, 19.0
22.979284425, 8.670, 21.0
23.031805556, 8.670, 23.0
23.084326687, 8.670, 22.0
23.136847817, 8.670, 24.0
23.189368948, 8.670, 28.0
23.241890079, 8.670, 27.0
23.294411209, 8.670, 20.0
23.346932340, 8.670, 20.0
23.399453471, 8.670, 20.0
23.451974602, 8.670, 28.0
23.504495732, 8.670, 12.0
23.557016863, 8.670, 25.0
23.609537994, 8.670, 19.0
23.662059124, 8.670, 16.0
23.714580255, 8.670, 21.0
23.767101386, 8.670, 33.0
23.819622517, 8.670, 25.0
23.872143647, 8.670, 25.0
23.924664778, 8.670, 23.0
23.977185909, 8.670, 19.0
24.029707039, 8.670, 22.0
24.082228170, 8.670, 12.0
24.134749301, 8.670, 23.0
24.187270432, 8.670, 22.0
24.239791562, 8.670, 25.0
24.292312693, 8.670, 17.0
24.344833824, 8.670, 25.0
24.397354954, 8.670, 27.0
24.449876085, 8.670, 21.0
24.502397216, 8.670, 30.0
24.554918346, 8.670, 25.0
24.607439477, 8.670, 26.0
24.659960608, 8.670, 30.0
24.712481739, 8.670, 17.0
24.765002869, 8.670, 13.0
24.817524000, 8.670, 25.0
24.870045131, 8.670, 23.0
24.922566261, 8.670, 28.0
24.975087392, 8.670, 38.0
25.027608523, 8.670, 27.0
25.080129654, 8.670, 26.0
25.132650784, 8.670, 30.0
25.185171915, 8.670, 32.0
25.237693046, 8.670, 23.0
25.290214176, 8.670, 25.0
25.342735307, 8.670, 30.0
25.395256438, 8.670, 28.0
25.447777569, 8.670, 28.0
25.500298699, 8.670, 27.0
25.552819830, 8.670, 28.0
25.605340961, 8.670, 28.0
25.657862091, 8.670, 32.0
25.710383222, 8.670, 35.0
25.762904353, 8.670, 20.0
25.815425483, 8.670, 25.0
25.867946614, 8.670, 28.0
25.920467745, 8.670, 30.0
25.972988876, 8.670, 27.0
26.025510006, 8.670, 24.0
26.078031137, 8.670, 21.0
26.130552268, 8.670, 28.0
26.183073398, 8.670, 25.0
26.235594529, 8.670, 18.0
26.288115660, 8.670, 31.0
26.340636791, 8.670, 18.0
26.393157921, 8.670, 25.0
26.445679052, 8.670, 24.0
26.498200183, 8.670, 25.0
26.550721313, 8.670, 35.0
26.603242444, 8.670, 32.0
26.655763575, 8.670, 33.0
26.708284706, 8.670, 32.0
26.760805836, 8.670, 35.0
26.813326967, 8.670, 40.0
26.865848098, 8.670, 45.0
26.918369228, 8.670, 60.0
26.970890359, 8.670, 73.0
27.023411490, 8.670, 126.0
27.075932621, 8.670, 1021.0
27.128453751, 8.670, 516.0
27.180974882, 8.670, 770.0
27.233496013, 8.670, 115.0
27.286017143, 8.670, 104.0
27.338538274, 8.670, 73.0
27.391059405, 8.670, 63.0
27.443580535, 8.670, 64.0
27.496101666, 8.670, 68.0
27.548622797, 8.670, 64.0
27.601143928, 8.670, 73.0
27.653665058, 8.670, 69.0
27.706186189, 8.670, 72.0
27.758707320, 8.670, 74.0
27.811228450, 8.670, 66.0
27.863749581, 8.670, 65.0
27.916270712, 8.670, 94.0
27.968791843, 8.670, 75.0
28.021312973, 8.670, 69.0
28.073834104, 8.670, 68.0
28.126355235, 8.670, 74.0
28.178876365, 8.670, 111.0
28.231397496, 8.670, 85.0
28.283918627, 8.670, 103.0
28.336439758, 8.670, 96.0
28.388960888, 8.670, 108.0
28.441482019, 8.670, 120.0
28.494003150, 8.670, 120.0
28.546524280, 8.670, 133.0
28.599045411, 8.670, 160.0
28.651566542, 8.670, 172.0
28.704087673, 8.670, 193.0
28.756608803, 8.670, 277.0
28.809129934, 8.670, 915.0
28.861651065, 8.670, 1090.0
28.914172195, 8.670, 445.0
28.966693326, 8.670, 400.0
29.019214457, 8.670, 443.0
29.071735587, 8.670, 898.0
29.124256718, 8.670, 602.0
29.176777849, 8.670, 704.0
29.229298980, 8.670, 778.0
29.281820110, 8.670, 840.0
29.334341241, 8.670, 911.0
29.386862372, 8.670, 1040.0
29.439383502, 8.670, 1104.0
29.491904633, 8.670, 1226.0
29.544425764, 8.670, 1393.0
29.596946895, 8.670, 1521.0
29.649468025, 8.670, 1597.0
29.701989156, 8.670, 1796.0
29.754510287, 8.670, 2094.0
29.807031417, 8.670, 2317.0
29.859552548, 8.670, 2774.0
29.912073679, 8.670, 3750.0
29.964594810, 8.670, 7947.0
30.017115940, 8.670, 12399.0
30.069637071, 8.670, 27364.0
30.122158202, 8.670, 1053335.0
30.174679332, 8.670, 79067.0
30.227200463, 8.670, 75238.0
30.279721594, 8.670, 8813.0
30.332242724, 8.670, 3988.0
30.384763855, 8.670, 2311.0
30.437284986, 8.670, 1653.0
30.489806117, 8.670, 1232.0
30.542327247, 8.670, 937.0
30.594848378, 8.670, 717.0
30.647369509, 8.670, 598.0
30.699890639, 8.670, 547.0
30.752411770, 8.670, 466.0
30.804932901, 8.670, 391.0
30.857454032, 8.670, 381.0
30.909975162, 8.670, 288.0
30.962496293, 8.670, 235.0
31.015017424, 8.670, 214.0
31.067538554, 8.670, 184.0
31.120059685, 8.670, 184.0
31.172580816, 8.670, 177.0
31.225101947, 8.670, 171.0
31.277623077, 8.670, 136.0
31.330144208, 8.670, 130.0
31.382665339, 8.670, 116.0
31.435186469, 8.670, 100.0
31.487707600, 8.670, 103.0
31.540228731, 8.670, 119.0
31.592749862, 8.670, 74.0
31.645270992, 8.670, 107.0
31.697792123, 8.670, 80.0
31.750313254, 8.670, 72.0
31.802834384, 8.670, 97.0
31.855355515, 8.670, 73.0
31.907876646, 8.670, 79.0
31.960397776, 8.670, 81.0
32.012918907, 8.670, 68.0
32.065440038, 8.670, 78.0
32.117961169, 8.670, 57.0
32.170482299, 8.670, 71.0
32.223003430, 8.670, 53.0
32.275524561, 8.670, 48.0
32.328045691, 8.670, 52.0
32.380566822, 8.670, 53.0
32.433087953, 8.670, 45.0
32.485609084, 8.670, 48.0
32.538130214, 8.670, 57.0
32.590651345, 8.670, 51.0
32.643172476, 8.670, 49.0
32.695693606, 8.670, 38.0
32.748214737, 8.670, 57.0
32.800735868, 8.670, 52.0
32.853256999, 8.670, 49.0
32.905778129, 8.670, 47.0
32.958299260, 8.670, 44.0
33.010820391, 8.670, 46.0
33.063341521, 8.670, 43.0
33.115862652, 8.670, 38.0
33.168383783, 8.670, 34.0
33.220904914, 8.670, 37.0
33.273426044, 8.670, 53.0
33.325947175, 8.670, 36.0
33.378468306, 8.670, 39.0
33.430989436, 8.670, 41.0
33.483510567, 8.670, 27.0
33.536031698, 8.670, 33.0
33.588552828, 8.670, 39.0
33.641073959, 8.670, 37.0
33.693595090, 8.670, 40.0
33.746116221, 8.670, 26.0
33.798637351, 8.670, 47.0
33.851158482, 8.670, 27.0
33.903679613, 8.670, 29.0
33.956200743, 8.670, 33.0
34.008721874, 8.670, 33.0
34.061243005, 8.670, 33.0
34.113764136, 8.670, 39.0
34.166285266, 8.670, 28.0
34.218806397, 8.670, 27.0
34.271327528, 8.670, 37.0
34.323848658, 8.670, 30.0
34.376369789, 8.670, 25.0
34.428890920, 8.670, 31.0
34.481412051, 8.670, 36.0
34.533933181, 8.670, 20.0
34.586454312, 8.670, 28.0
34.638975443, 8.670, 25.0
34.691496573, 8.670, 25.0
34.744017704, 8.670, 34.0
34.796538835, 8.670, 28.0
34.849059965, 8.670, 25.0
34.901581096, 8.670, 17.0
34.954102227, 8.670, 30.0
35.006623358, 8.670, 32.0
35.059144488, 8.670, 21.0
35.111665619, 8.670, 23.0
35.164186750, 8.670, 39.0
35.216707880, 8.670, 21.0
35.269229011, 8.670, 23.0
35.321750142, 8.670, 23.0
35.374271273, 8.670, 26.0
35.426792403, 8.670, 20.0
35.479313534, 8.670, 21.0
35.531834665, 8.670, 16.0
35.584355795, 8.670, 23.0
35.636876926, 8.670, 24.0
35.689398057, 8.670, 27.0
35.741919188, 8.670, 31.0
35.794440318, 8.670, 26.0
35.846961449, 8.670, 21.0
35.899482580, 8.670, 19.0
35.952003710, 8.670, 26.0
36.004524841, 8.670, 18.0
36.057045972, 8.670, 28.0
36.109567103, 8.670, 20.0
36.162088233, 8.670, 34.0
36.214609364, 8.670, 26.0
36.267130495, 8.670, 23.0
36.319651625, 8.670, 15.0
36.372172756, 8.670, 21.0
36.424693887, 8.670, 23.0
36.477215017, 8.670, 31.0
36.529736148, 8.670, 28.0
36.582257279, 8.670, 22.0
36.634778410, 8.670, 17.0
36.687299540, 8.670, 13.0
36.739820671, 8.670, 16.0
36.792341802, 8.670, 13.0
36.844862932, 8.670, 19.0
36.897384063, 8.670, 25.0
36.949905194, 8.670, 28.0
37.002426325, 8.670, 21.0
37.054947455, 8.670, 17.0
37.107468586, 8.670, 18.0
37.159989717, 8.670, 19.0
37.212510847, 8.670, 14.0
37.265031978, 8.670, 21.0
37.317553109, 8.670, 16.0
37.370074240, 8.670, 21.0
37.422595370, 8.670, 12.0
37.475116501, 8.670, 18.0
37.527637632, 8.670, 18.0
37.580158762, 8.670, 22.0
37.632679893, 8.670, 26.0
37.685201024, 8.670, 26.0
37.737722155, 8.670, 21.0
37.790243285, 8.670, 19.0
37.842764416, 8.670, 25.0
37.895285547, 8.670, 23.0
37.947806677, 8.670, 24.0
38.000327808, 8.670, 13.0
38.052848939, 8.670, 14.0
38.105370069, 8.670, 18.0
38.157891200, 8.670, 20.0
38.210412331, 8.670, 26.0
38.262933462, 8.670, 15.0
38.315454592, 8.670, 17.0
38.367975723, 8.670, 15.0
38.420496854, 8.670, 14.0
38.473017984, 8.670, 21.0
38.525539115, 8.670, 11.0
38.578060246, 8.670, 18.0
38.630581377, 8.670, 17.0
38.683102507, 8.670, 18.0
38.735623638, 8.670, 15.0
38.788144769, 8.670, 15.0
38.840665899, 8.670, 28.0
38.893187030, 8.670, 18.0
38.945708161, 8.670, 13.0
38.998229292, 8.670, 21.0
39.050750422, 8.670, 19.0
39.103271553, 8.670, 9.0
39.155792684, 8.670, 16.0
39.208313814, 8.670, 16.0
39.260834945, 8.670, 19.0
39.313356076, 8.670, 14.0
39.365877206, 8.670, 21.0
39.418398337, 8.670, 22.0
39.470919468, 8.670, 23.0
39.523440599, 8.670, 25.0
39.575961729, 8.670, 27.0
39.628482860, 8.670, 26.0
39.681003991, 8.670, 16.0
39.733525121, 8.670, 18.0
39.786046252, 8.670, 19.0
39.838567383, 8.670, 22.0
39.891088514, 8.670, 15.0
39.943609644, 8.670, 25.0
39.996130775, 8.670, 8.0
40.048651906, 8.670, 17.0
40.101173036, 8.670, 22.0
40.153694167, 8.670, 18.0
40.206215298, 8.670, 25.0
40.258736429, 8.670, 19.0
40.311257559, 8.670, 18.0
40.363778690, 8.670, 25.0
40.416299821, 8.670, 22.0
40.468820951, 8.670, 17.0
40.521342082, 8.670, 17.0
40.573863213, 8.670, 21.0
40.626384344, 8.670, 23.0
40.678905474, 8.670, 27.0
40.731426605, 8.670, 17.0
40.783947736, 8.670, 22.0
40.836468866, 8.670, 24.0
40.888989997, 8.670, 18.0
40.941511128, 8.670, 26.0
40.994032258, 8.670, 28.0
41.046553389, 8.670, 30.0
41.099074520, 8.670, 46.0
41.151595651, 8.670, 154.0
41.204116781, 8.670, 107.0
41.256637912, 8.670, 193.0
41.309159043, 8.670, 43.0
41.361680173, 8.670, 33.0
41.414201304, 8.670, 26.0
41.466722435, 8.670, 25.0
41.519243566, 8.670, 31.0
41.571764696, 8.670, 33.0
41.624285827, 8.670, 31.0
41.676806958, 8.670, 24.0
41.729328088, 8.670, 25.0
41.781849219, 8.670, 22.0
41.834370350, 8.670, 21.0
41.886891481, 8.670, 22.0
41.939412611, 8.670, 31.0
41.991933742, 8.670, 23.0
42.044454873, 8.670, 34.0
42.096976003, 8.670, 38.0
42.149497134, 8.670, 34.0
42.202018265, 8.670, 24.0
42.254539395, 8.670, 37.0
42.307060526, 8.670, 47.0
42.359581657, 8.670, 50.0
42.412102788, 8.670, 54.0
42.464623918, 8.670, 52.0
42.517145049, 8.670, 55.0
42.569666180, 8.670, 47.0
42.622187310, 8.670, 38.0
42.674708441, 8.670, 40.0
42.727229572, 8.670, 33.0
42.779750703, 8.670, 29.0
42.832271833, 8.670, 30.0
42.884792964, 8.670, 34.0
42.937314095, 8.670, 27.0
42.989835225, 8.670, 28.0
43.042356356, 8.670, 39.0
43.094877487, 8.670, 24.0
43.147398618, 8.670, 37.0
43.199919748, 8.670, 37.0
43.252440879, 8.670, 28.0
43.304962010, 8.670, 30.0
43.357483140, 8.670, 28.0
43.410004271, 8.670, 46.0
43.462525402, 8.670, 36.0
43.515046533, 8.670, 42.0
43.567567663, 8.670, 33.0
43.620088794, 8.670, 50.0
43.672609925, 8.670, 45.0
43.725131055, 8.670, 52.0
43.777652186, 8.670, 73.0
43.830173317, 8.670, 138.0
43.882694447, 8.670, 209.0
43.935215578, 8.670, 60.0
43.987736709, 8.670, 50.0
44.040257840, 8.670, 56.0
44.092778970, 8.670, 68.0
44.145300101, 8.670, 50.0
44.197821232, 8.670, 127.0
44.250342362, 8.670, 92.0
44.302863493, 8.670, 100.0
44.355384624, 8.670, 77.0
44.407905755, 8.670, 74.0
44.460426885, 8.670, 107.0
44.512948016, 8.670, 97.0
44.565469147, 8.670, 105.0
44.617990277, 8.670, 102.0
44.670511408, 8.670, 100.0
44.723032539, 8.670, 115.0
44.775553670, 8.670, 133.0
44.828074800, 8.670, 157.0
44.880595931, 8.670, 161.0
44.933117062, 8.670, 142.0
44.985638192, 8.670, 186.0
45.038159323, 8.670, 166.0
45.090680454, 8.670, 195.0
45.143201585, 8.670, 177.0
45.195722715, 8.670, 230.0
45.248243846, 8.670, 231.0
45.300764977, 8.670, 230.0
45.353286107, 8.670, 260.0
45.405807238, 8.670, 323.0
45.458328369, 8.670, 343.0
45.510849499, 8.670, 411.0
45.563370630, 8.670, 486.0
45.615891761, 8.670, 708.0
45.668412892, 8.670, 1341.0
45.720934022, 8.670, 1316.0
45.773455153, 8.670, 1989.0
45.825976284, 8.670, 6137.0
45.878497414, 8.670, 155974.0
45.931018545, 8.670, 8500.0
45.983539676, 8.670, 25326.0
46.036060807, 8.670, 9334.0
46.088581937, 8.670, 1491.0
46.141103068, 8.670, 817.0
46.193624199, 8.670, 501.0
46.246145329, 8.670, 361.0
46.298666460, 8.670, 242.0
46.351187591, 8.670, 206.0
46.403708722, 8.670, 188.0
46.456229852, 8.670, 164.0
46.508750983, 8.670, 127.0
46.561272114, 8.670, 110.0
46.613793244, 8.670, 115.0
46.666314375, 8.670, 99.0
46.718835506, 8.670, 99.0
46.771356636, 8.670, 78.0
46.823877767, 8.670, 66.0
46.876398898, 8.670, 72.0
46.928920029, 8.670, 74.0
46.981441159, 8.670, 45.0
47.033962290, 8.670, 45.0
47.086483421, 8.670, 53.0
47.139004551, 8.670, 45.0
47.191525682, 8.670, 34.0
47.244046813, 8.670, 53.0
47.296567944, 8.670, 51.0
47.349089074, 8.670, 31.0
47.401610205, 8.670, 37.0
47.454131336, 8.670, 35.0
47.506652466, 8.670, 25.0
47.559173597, 8.670, 32.0
47.611694728, 8.670, 44.0
47.664215859, 8.670, 34.0
47.716736989, 8.670, 29.0
47.769258120, 8.670, 36.0
47.821779251, 8.670, 30.0
47.874300381, 8.670, 30.0
47.926821512, 8.670, 33.0
47.979342643, 8.670, 21.0
48.031863774, 8.670, 32.0
48.084384904, 8.670, 25.0
48.136906035, 8.670, 17.0
48.189427166, 8.670, 21.0
48.241948296, 8.670, 30.0
48.294469427, 8.670, 34.0
48.346990558, 8.670, 22.0
48.399511688, 8.670, 19.0
48.452032819, 8.670, 23.0
48.504553950, 8.670, 21.0
48.557075081, 8.670, 30.0
48.609596211, 8.670, 20.0
48.662117342, 8.670, 24.0
48.714638473, 8.670, 23.0
48.767159603, 8.670, 12.0
48.819680734, 8.670, 23.0
48.872201865, 8.670, 24.0
48.924722996, 8.670, 25.0
48.977244126, 8.670, 26.0
49.029765257, 8.670, 25.0
49.082286388, 8.670, 37.0
49.134807518, 8.670, 26.0
49.187328649, 8.670, 28.0
49.239849780, 8.670, 20.0
49.292370911, 8.670, 23.0
49.344892041, 8.670, 28.0
49.397413172, 8.670, 18.0
49.449934303, 8.670, 28.0
49.502455433, 8.670, 17.0
49.554976564, 8.670, 24.0
49.607497695, 8.670, 30.0
49.660018826, 8.670, 16.0
49.712539956, 8.670, 21.0
49.765061087, 8.670, 21.0
49.817582218, 8.670, 28.0
49.870103348, 8.670, 15.0
49.922624479, 8.670, 18.0
49.975145610, 8.670, 21.0
50.027666740, 8.670, 30.0
50.080187871, 8.670, 17.0
50.132709002, 8.670, 16.0
50.185230133, 8.670, 20.0
50.237751263, 8.670, 21.0
50.290272394, 8.670, 16.0
50.342793525, 8.670, 26.0
50.395314655, 8.670, 11.0
50.447835786, 8.670, 25.0
50.500356917, 8.670, 24.0
50.552878048, 8.670, 23.0
50.605399178, 8.670, 21.0
50.657920309, 8.670, 17.0
50.710441440, 8.670, 14.0
50.762962570, 8.670, 13.0
50.815483701, 8.670, 18.0
50.868004832, 8.670, 16.0
50.920525963, 8.670, 21.0
50.973047093, 8.670, 15.0
51.025568224, 8.670, 15.0
51.078089355, 8.670, 11.0
51.130610485, 8.670, 16.0
51.183131616, 8.670, 22.0
51.235652747, 8.670, 32.0
51.288173877, 8.670, 19.0
51.340695008, 8.670, 14.0
51.393216139, 8.670, 15.0
51.445737270, 8.670, 22.0
51.498258400, 8.670, 17.0
51.550779531, 8.670, 20.0
51.603300662, 8.670, 21.0
51.655821792, 8.670, 18.0
51.708342923, 8.670, 15.0
51.760864054, 8.670, 21.0
51.813385185, 8.670, 19.0
51.865906315, 8.670, 13.0
51.918427446, 8.670, 9.0
51.970948577, 8.670, 26.0
52.023469707, 8.670, 16.0
52.075990838, 8.670, 19.0
52.128511969, 8.670, 17.0
52.181033100, 8.670, 14.0
52.233554230, 8.670, 10.0
52.286075361, 8.670, 14.0
52.338596492, 8.670, 18.0
52.391117622, 8.670, 11.0
52.443638753, 8.670, 15.0
52.496159884, 8.670, 20.0
52.548681015, 8.670, 16.0
52.601202145, 8.670, 21.0
52.653723276, 8.670, 20.0
52.706244407, 8.670, 15.0
52.758765537, 8.670, 21.0
52.811286668, 8.670, 25.0
52.863807799, 8.670, 16.0
52.916328929, 8.670, 16.0
52.968850060, 8.670, 15.0
53.021371191, 8.670, 18.0
53.073892322, 8.670, 19.0
53.126413452, 8.670, 20.0
53.178934583, 8.670, 19.0
53.231455714, 8.670, 10.0
53.283976844, 8.670, 14.0
53.336497975, 8.670, 15.0
53.389019106, 8.670, 12.0
53.441540237, 8.670, 15.0
53.494061367, 8.670, 17.0
53.546582498, 8.670, 8.0
53.599103629, 8.670, 18.0
53.651624759, 8.670, 16.0
53.704145890, 8.670, 14.0
53.756667021, 8.670, 20.0
53.809188152, 8.670, 24.0
53.861709282, 8.670, 17.0
53.914230413, 8.670, 13.0
53.966751544, 8.670, 18.0
54.019272674, 8.670, 20.0
54.071793805, 8.670, 12.0
54.124314936, 8.670, 15.0
54.176836067, 8.670, 8.0
54.229357197, 8.670, 14.0
54.281878328, 8.670, 15.0
54.334399459, 8.670, 25.0
54.386920589, 8.670, 13.0
54.439441720, 8.670, 12.0
54.491962851, 8.670, 7.0
54.544483981, 8.670, 12.0
54.597005112, 8.670, 19.0
54.649526243, 8.670, 18.0
54.702047374, 8.670, 25.0
54.754568504, 8.670, 15.0
54.807089635, 8.670, 14.0
54.859610766, 8.670, 19.0
54.912131896, 8.670, 18.0
54.964653027, 8.670, 20.0
55.017174158, 8.670, 18.0
55.069695289, 8.670, 15.0
55.122216419, 8.670, 13.0
55.174737550, 8.670, 12.0
55.227258681, 8.670, 11.0
55.279779811, 8.670, 17.0
55.332300942, 8.670, 19.0
55.384822073, 8.670, 24.0
55.437343204, 8.670, 23.0
55.489864334, 8.670, 12.0
55.542385465, 8.670, 22.0
55.594906596, 8.670, 17.0
55.647427726, 8.670, 20.0
55.699948857, 8.670, 20.0
55.752469988, 8.670, 20.0
55.804991118, 8.670, 31.0
55.857512249, 8.670, 27.0
55.910033380, 8.670, 116.0
55.962554511, 8.670, 112.0
56.015075641, 8.670, 198.0
56.067596772, 8.670, 54.0
56.120117903, 8.670, 31.0
56.172639033, 8.670, 20.0
56.225160164, 8.670, 21.0
56.277681295, 8.670, 28.0
56.330202426, 8.670, 22.0
56.382723556, 8.670, 23.0
56.435244687, 8.670, 31.0
56.487765818, 8.670, 18.0
56.540286948, 8.670, 23.0
56.592808079, 8.670, 20.0
56.645329210, 8.670, 19.0
56.697850341, 8.670, 18.0
56.750371471, 8.670, 15.0
56.802892602, 8.670, 22.0
56.855413733, 8.670, 24.0
56.907934863, 8.670, 29.0
56.960455994, 8.670, 12.0
57.012977125, 8.670, 17.0
57.065498256, 8.670, 21.0
57.118019386, 8.670, 18.0
57.170540517, 8.670, 18.0
57.223061648, 8.670, 34.0
57.275582778, 8.670, 17.0
57.328103909, 8.670, 17.0
57.380625040, 8.670, 16.0
57.433146170, 8.670, 18.0
57.485667301, 8.670, 27.0
57.538188432, 8.670, 21.0
57.590709563, 8.670, 29.0
57.643230693, 8.670, 19.0
57.695751824, 8.670, 21.0
57.748272955, 8.670, 24.0
57.800794085, 8.670, 20.0
57.853315216, 8.670, 21.0
57.905836347, 8.670, 25.0
57.958357478, 8.670, 26.0
58.010878608, 8.670, 19.0
58.063399739, 8.670, 19.0
58.115920870, 8.670, 27.0
58.168442000, 8.670, 15.0
58.220963131, 8.670, 33.0
58.273484262, 8.670, 19.0
58.326005393, 8.670, 24.0
58.378526523, 8.670, 17.0
58.431047654, 8.670, 20.0
58.483568785, 8.670, 29.0
58.536089915, 8.670, 25.0
58.588611046, 8.670, 27.0
58.641132177, 8.670, 24.0
58.693653308, 8.670, 20.0
58.746174438, 8.670, 24.0
58.798695569, 8.670, 40.0
58.851216700, 8.670, 23.0
58.903737830, 8.670, 27.0
58.956258961, 8.670, 24.0
59.008780092, 8.670, 18.0
59.061301222, 8.670, 24.0
59.113822353, 8.670, 28.0
59.166343484, 8.670, 26.0
59.218864615, 8.670, 39.0
59.271385745, 8.670, 27.0
59.323906876, 8.670, 35.0
59.376428007, 8.670, 23.0
59.428949137, 8.670, 37.0
59.481470268, 8.670, 40.0
59.533991399, 8.670, 40.0
59.586512530, 8.670, 50.0
59.639033660, 8.670, 52.0
59.691554791, 8.670, 99.0
59.744075922, 8.670, 263.0
59.796597052, 8.670, 89.0
59.849118183, 8.670, 64.0
59.901639314, 8.670, 42.0
59.954160445, 8.670, 45.0
60.006681575, 8.670, 49.0
60.059202706, 8.670, 40.0
60.111723837, 8.670, 54.0
60.164244967, 8.670, 71.0
60.216766098, 8.670, 93.0
60.269287229, 8.670, 80.0
60.321808359, 8.670, 72.0
60.374329490, 8.670, 74.0
60.426850621, 8.670, 71.0
60.479371752, 8.670, 63.0
60.531892882, 8.670, 83.0
60.584414013, 8.670, 76.0
60.636935144, 8.670, 82.0
60.689456274, 8.670, 82.0
60.741977405, 8.670, 88.0
60.794498536, 8.670, 110.0
60.847019667, 8.670, 93.0
60.899540797, 8.670, 90.0
60.952061928, 8.670, 111.0
61.004583059, 8.670, 105.0
61.057104189, 8.670, 117.0
61.109625320, 8.670, 151.0
61.162146451, 8.670, 131.0
61.214667582, 8.670, 142.0
61.267188712, 8.670, 145.0
61.319709843, 8.670, 155.0
61.372230974, 8.670, 143.0
61.424752104, 8.670, 157.0
61.477273235, 8.670, 165.0
61.529794366, 8.670, 172.0
61.582315497, 8.670, 183.0
61.634836627, 8.670, 188.0
61.687357758, 8.670, 210.0
61.739878889, 8.670, 223.0
61.792400019, 8.670, 234.0
61.844921150, 8.670, 242.0
61.897442281, 8.670, 267.0
61.949963411, 8.670, 294.0
62.002484542, 8.670, 348.0
62.055005673, 8.670, 398.0
62.107526804, 8.670, 383.0
62.160047934, 8.670, 435.0
62.212569065, 8.670, 555.0
62.265090196, 8.670, 789.0
62.317611326, 8.670, 1157.0
62.370132457, 8.670, 1264.0
62.422653588, 8.670, 1326.0
62.475174719, 8.670, 1754.0
62.527695849, 8.670, 3528.0
62.580216980, 8.670, 14393.0
62.632738111, 8.670, 96881.0
62.685259241, 8.670, 7997.0
62.737780372, 8.670, 5553.0
62.790301503, 8.670, 48339.0
62.842822634, 8.670, 7390.0
62.895343764, 8.670, 1890.0
62.947864895, 8.670, 1045.0
63.000386026, 8.670, 740.0
63.052907156, 8.670, 608.0
63.105428287, 8.670, 466.0
63.157949418, 8.670, 364.0
63.210470549, 8.670, 302.0
63.262991679, 8.670, 291.0
63.315512810, 8.670, 228.0
63.368033941, 8.670, 214.0
63.420555071, 8.670, 204.0
63.473076202, 8.670, 165.0
63.525597333, 8.670, 139.0
63.578118463, 8.670, 140.0
63.630639594, 8.670, 136.0
63.683160725, 8.670, 127.0
63.735681856, 8.670, 104.0
63.788202986, 8.670, 81.0
63.840724117, 8.670, 92.0
63.893245248, 8.670, 75.0
63.945766378, 8.670, 88.0
63.998287509, 8.670, 69.0
64.050808640, 8.670, 67.0
64.103329771, 8.670, 54.0
64.155850901, 8.670, 55.0
64.208372032, 8.670, 57.0
64.260893163, 8.670, 54.0
64.313414293, 8.670, 60.0
64.365935424, 8.670, 73.0
64.418456555, 8.670, 52.0
64.470977686, 8.670, 64.0
64.523498816, 8.670, 40.0
64.576019947, 8.670, 38.0
64.628541078, 8.670, 45.0
64.681062208, 8.670, 39.0
64.733583339, 8.670, 41.0
64.786104470, 8.670, 39.0
64.838625600, 8.670, 32.0
64.891146731, 8.670, 44.0
64.943667862, 8.670, 41.0
64.996188993, 8.670, 34.0
65.048710123, 8.670, 34.0
65.101231254, 8.670, 33.0
65.153752385, 8.670, 29.0
65.206273515, 8.670, 25.0
65.258794646, 8.670, 42.0
65.311315777, 8.670, 38.0
65.363836908, 8.670, 31.0
65.416358038, 8.670, 31.0
65.468879169, 8.670, 33.0
65.521400300, 8.670, 28.0
65.573921430, 8.670, 28.0
65.626442561, 8.670, 17.0
65.678963692, 8.670, 28.0
65.731484823, 8.670, 28.0
65.784005953, 8.670, 30.0
65.836527084, 8.670, 20.0
65.889048215, 8.670, 29.0
65.941569345, 8.670, 25.0
65.994090476, 8.670, 23.0
66.046611607, 8.670, 21.0
66.099132738, 8.670, 20.0
66.151653868, 8.670, 28.0
66.204174999, 8.670, 21.0
66.256696130, 8.670, 26.0
66.309217260, 8.670, 21.0
66.361738391, 8.670, 21.0
66.414259522, 8.670, 29.0
66.466780652, 8.670, 23.0
66.519301783, 8.670, 16.0
66.571822914, 8.670, 20.0
66.624344045, 8.670, 19.0
66.676865175, 8.670, 24.0
66.729386306, 8.670, 20.0
66.781907437, 8.670, 15.0
66.834428567, 8.670, 18.0
66.886949698, 8.670, 26.0
66.939470829, 8.670, 22.0
66.991991960, 8.670, 30.0
67.044513090, 8.670, 22.0
67.097034221, 8.670, 24.0
67.149555352, 8.670, 15.0
67.202076482, 8.670, 23.0
67.254597613, 8.670, 15.0
67.307118744, 8.670, 15.0
67.359639875, 8.670, 19.0
67.412161005, 8.670, 20.0
67.464682136, 8.670, 21.0
67.517203267, 8.670, 23.0
67.569724397, 8.670, 22.0
67.622245528, 8.670, 23.0
67.674766659, 8.670, 21.0
67.727287790, 8.670, 21.0
67.779808920, 8.670, 16.0
67.832330051, 8.670, 14.0
67.884851182, 8.670, 18.0
67.937372312, 8.670, 11.0
67.989893443, 8.670, 14.0
68.042414574, 8.670, 20.0
68.094935704, 8.670, 19.0
68.147456835, 8.670, 16.0
68.199977966, 8.670, 23.0
68.252499097, 8.670, 29.0
68.305020227, 8.670, 19.0
68.357541358, 8.670, 18.0
68.410062489, 8.670, 15.0
68.462583619, 8.670, 16.0
68.515104750, 8.670, 23.0
68.567625881, 8.670, 18.0
68.620147012, 8.670, 27.0
68.672668142, 8.670, 24.0
68.725189273, 8.670, 13.0
68.777710404, 8.670, 13.0
68.830231534, 8.670, 16.0
68.882752665, 8.670, 25.0
68.935273796, 8.670, 22.0
68.987794927, 8.670, 16.0
69.040316057, 8.670, 24.0
69.092837188, 8.670, 10.0
69.145358319, 8.670, 17.0
69.197879449, 8.670, 18.0
69.250400580, 8.670, 18.0
69.302921711, 8.670, 22.0
69.355442841, 8.670, 17.0
69.407963972, 8.670, 23.0
69.460485103, 8.670, 9.0
69.513006234, 8.670, 22.0
69.565527364, 8.670, 13.0
69.618048495, 8.670, 22.0
69.670569626, 8.670, 18.0
69.723090756, 8.670, 16.0
69.775611887, 8.670, 15.0
69.828133018, 8.670, 11.0
69.880654149, 8.670, 18.0
69.933175279, 8.670, 11.0
69.985696410, 8.670, 21.0