File: Data/Figure3/230920_A_0.2_201Phi-scan.csv
[Measurement conditions]
Sample identification,
Comment - 1,"Configuration=Chi-Phi-Z stage 240 mm (reflection), Owner=User-1, Creation date=10/23/2015 4:48:55 PM"
Comment - 2,"Goniometer=Theta/Theta; Minimum step size 2Theta:0.0001; Minimum step size Omega:0.0001"
Comment - 3,"Sample stage=Chi-Phi-z stage 240 mm (reflection); Minimum step size Phi:0.01; Minimum step size Chi:0.01; Minimum step size Z:0.001"
Comment - 4,"Diffractometer system=EMPYREAN"
Comment - 5,"Measurement program=C:\PANalytical\Data Collector\Programs\Yuki-Phi-scan.xrdmp, Identifier={48E3FB3F-1168-45E7-99C6-10C9CB5D9D97}"
Comment - 6,"Fine Calibration Offset for 2Theta = 0.0141 deg"
Comment - 7,"Fine Calibration Offset for Omega = 0.2992 deg"
Anode material,Cu
K-Alpha1 wavelength,1.5405980
K-Alpha2 wavelength,1.5444260
Ratio K-Alpha2/K-Alpha1,0.500
Divergence slit,Fixed,0.19mm
Monochromator used,NO
Generator voltage, 45
Tube current, 40
File date and time,26/Sep/2023 11:56
Unit cell,
h k l, 0 0 0
Scan axis,Phi
Scan range,0.000,360.000
Scan step size,0.2000000
No. of points, 1800
Scan type,CONTINUOUS
2Theta,34.0600
Omega,16.8577
Psi,26.57
Z,9.265
Time per step,0.176
[Scan points]
Angle, TimePerStep, Intensity
0.100, 0.176, 4.0
0.500, 0.176, 1.0
0.900, 0.176, 4.0
1.300, 0.176, 4.0
1.700, 0.176, 3.0
2.100, 0.176, 2.0
2.500, 0.176, 6.0
2.900, 0.176, 6.0
3.300, 0.176, 3.0
3.700, 0.176, 2.0
4.100, 0.176, 5.0
4.500, 0.176, 4.0
4.900, 0.176, 1.0
5.300, 0.176, 3.0
5.700, 0.176, 3.0
6.100, 0.176, 3.0
6.500, 0.176, 0.0
6.900, 0.176, 1.0
7.300, 0.176, 3.0
7.700, 0.176, 0.0
8.100, 0.176, 1.0
8.500, 0.176, 2.0
8.900, 0.176, 1.0
9.300, 0.176, 0.0
9.700, 0.176, 2.0
10.100, 0.176, 1.0
10.500, 0.176, 2.0
10.900, 0.176, 0.0
11.300, 0.176, 1.0
11.700, 0.176, 2.0
12.100, 0.176, 0.0
12.500, 0.176, 0.0
12.900, 0.176, 0.0
13.300, 0.176, 0.0
13.700, 0.176, 1.0
14.100, 0.176, 3.0
14.500, 0.176, 0.0
14.900, 0.176, 1.0
15.300, 0.176, 0.0
15.700, 0.176, 0.0
16.100, 0.176, 1.0
16.500, 0.176, 0.0
16.900, 0.176, 1.0
17.300, 0.176, 3.0
17.700, 0.176, 0.0
18.100, 0.176, 0.0
18.500, 0.176, 0.0
18.900, 0.176, 4.0
19.300, 0.176, 0.0
19.700, 0.176, 0.0
20.100, 0.176, 1.0
20.500, 0.176, 0.0
20.900, 0.176, 0.0
21.300, 0.176, 0.0
21.700, 0.176, 1.0
22.100, 0.176, 1.0
22.500, 0.176, 0.0
22.900, 0.176, 0.0
23.300, 0.176, 1.0
23.700, 0.176, 0.0
24.100, 0.176, 0.0
24.500, 0.176, 1.0
24.900, 0.176, 0.0
25.300, 0.176, 0.0
25.700, 0.176, 1.0
26.100, 0.176, 1.0
26.500, 0.176, 2.0
26.900, 0.176, 3.0
27.300, 0.176, 0.0
27.700, 0.176, 1.0
28.100, 0.176, 0.0
28.500, 0.176, 1.0
28.900, 0.176, 0.0
29.300, 0.176, 0.0
29.700, 0.176, 0.0
30.100, 0.176, 1.0
30.500, 0.176, 1.0
30.900, 0.176, 0.0
31.300, 0.176, 3.0
31.700, 0.176, 1.0
32.100, 0.176, 0.0
32.500, 0.176, 0.0
32.900, 0.176, 0.0
33.300, 0.176, 0.0
33.700, 0.176, 1.0
34.100, 0.176, 1.0
34.500, 0.176, 1.0
34.900, 0.176, 1.0
35.300, 0.176, 0.0
35.700, 0.176, 0.0
36.100, 0.176, 1.0
36.500, 0.176, 0.0
36.900, 0.176, 0.0
37.300, 0.176, 0.0
37.700, 0.176, 0.0
38.100, 0.176, 2.0
38.500, 0.176, 0.0
38.900, 0.176, 1.0
39.300, 0.176, 1.0
39.700, 0.176, 0.0
40.100, 0.176, 0.0
40.500, 0.176, 1.0
40.900, 0.176, 1.0
41.300, 0.176, 1.0
41.700, 0.176, 1.0
42.100, 0.176, 0.0
42.500, 0.176, 0.0
42.900, 0.176, 1.0
43.300, 0.176, 2.0
43.700, 0.176, 2.0
44.100, 0.176, 3.0
44.500, 0.176, 0.0
44.900, 0.176, 0.0
45.300, 0.176, 0.0
45.700, 0.176, 1.0
46.100, 0.176, 2.0
46.500, 0.176, 0.0
46.900, 0.176, 1.0
47.300, 0.176, 0.0
47.700, 0.176, 0.0
48.100, 0.176, 1.0
48.500, 0.176, 0.0
48.900, 0.176, 0.0
49.300, 0.176, 0.0
49.700, 0.176, 1.0
50.100, 0.176, 1.0
50.500, 0.176, 0.0
50.900, 0.176, 0.0
51.300, 0.176, 1.0
51.700, 0.176, 0.0
52.100, 0.176, 2.0
52.500, 0.176, 2.0
52.900, 0.176, 1.0
53.300, 0.176, 0.0
53.700, 0.176, 0.0
54.100, 0.176, 3.0
54.500, 0.176, 0.0
54.900, 0.176, 1.0
55.300, 0.176, 2.0
55.700, 0.176, 0.0
56.100, 0.176, 1.0
56.500, 0.176, 0.0
56.900, 0.176, 0.0
57.300, 0.176, 0.0
57.700, 0.176, 1.0
58.100, 0.176, 3.0
58.500, 0.176, 1.0
58.900, 0.176, 1.0
59.300, 0.176, 1.0
59.700, 0.176, 1.0
60.100, 0.176, 4.0
60.500, 0.176, 0.0
60.900, 0.176, 0.0
61.300, 0.176, 0.0
61.700, 0.176, 0.0
62.100, 0.176, 1.0
62.500, 0.176, 0.0
62.900, 0.176, 2.0
63.300, 0.176, 1.0
63.700, 0.176, 0.0
64.100, 0.176, 2.0
64.500, 0.176, 3.0
64.900, 0.176, 1.0
65.300, 0.176, 0.0
65.700, 0.176, 0.0
66.100, 0.176, 2.0
66.500, 0.176, 0.0
66.900, 0.176, 1.0
67.300, 0.176, 1.0
67.700, 0.176, 3.0
68.100, 0.176, 3.0
68.500, 0.176, 1.0
68.900, 0.176, 2.0
69.300, 0.176, 3.0
69.700, 0.176, 2.0
70.100, 0.176, 2.0
70.500, 0.176, 0.0
70.900, 0.176, 1.0
71.300, 0.176, 1.0
71.700, 0.176, 0.0
72.100, 0.176, 0.0
72.500, 0.176, 1.0
72.900, 0.176, 2.0
73.300, 0.176, 2.0
73.700, 0.176, 2.0
74.100, 0.176, 2.0
74.500, 0.176, 1.0
74.900, 0.176, 3.0
75.300, 0.176, 1.0
75.700, 0.176, 2.0
76.100, 0.176, 4.0
76.500, 0.176, 1.0
76.900, 0.176, 2.0
77.300, 0.176, 6.0
77.700, 0.176, 7.0
78.100, 0.176, 5.0
78.500, 0.176, 2.0
78.900, 0.176, 3.0
79.300, 0.176, 6.0
79.700, 0.176, 2.0
80.100, 0.176, 4.0
80.500, 0.176, 5.0
80.900, 0.176, 4.0
81.300, 0.176, 6.0
81.700, 0.176, 8.0
82.100, 0.176, 9.0
82.500, 0.176, 14.0
82.900, 0.176, 14.0
83.300, 0.176, 23.0
83.700, 0.176, 56.0
84.100, 0.176, 4470.0
84.500, 0.176, 3071.0
84.900, 0.176, 21.0
85.300, 0.176, 13.0
85.700, 0.176, 10.0
86.100, 0.176, 9.0
86.500, 0.176, 1.0
86.900, 0.176, 2.0
87.300, 0.176, 2.0
87.700, 0.176, 3.0
88.100, 0.176, 3.0
88.500, 0.176, 5.0
88.900, 0.176, 2.0
89.300, 0.176, 4.0
89.700, 0.176, 3.0
90.100, 0.176, 3.0
90.500, 0.176, 1.0
90.900, 0.176, 2.0
91.300, 0.176, 1.0
91.700, 0.176, 2.0
92.100, 0.176, 3.0
92.500, 0.176, 2.0
92.900, 0.176, 0.0
93.300, 0.176, 0.0
93.700, 0.176, 1.0
94.100, 0.176, 0.0
94.500, 0.176, 3.0
94.900, 0.176, 2.0
95.300, 0.176, 1.0
95.700, 0.176, 0.0
96.100, 0.176, 3.0
96.500, 0.176, 1.0
96.900, 0.176, 2.0
97.300, 0.176, 2.0
97.700, 0.176, 0.0
98.100, 0.176, 2.0
98.500, 0.176, 2.0
98.900, 0.176, 1.0
99.300, 0.176, 3.0
99.700, 0.176, 0.0
100.100, 0.176, 0.0
100.500, 0.176, 1.0
100.900, 0.176, 1.0
101.300, 0.176, 1.0
101.700, 0.176, 0.0
102.100, 0.176, 2.0
102.500, 0.176, 2.0
102.900, 0.176, 1.0
103.300, 0.176, 0.0
103.700, 0.176, 0.0
104.100, 0.176, 0.0
104.500, 0.176, 2.0
104.900, 0.176, 1.0
105.300, 0.176, 1.0
105.700, 0.176, 1.0
106.100, 0.176, 1.0
106.500, 0.176, 0.0
106.900, 0.176, 0.0
107.300, 0.176, 0.0
107.700, 0.176, 1.0
108.100, 0.176, 1.0
108.500, 0.176, 1.0
108.900, 0.176, 0.0
109.300, 0.176, 2.0
109.700, 0.176, 0.0
110.100, 0.176, 1.0
110.500, 0.176, 0.0
110.900, 0.176, 1.0
111.300, 0.176, 3.0
111.700, 0.176, 1.0
112.100, 0.176, 0.0
112.500, 0.176, 0.0
112.900, 0.176, 0.0
113.300, 0.176, 2.0
113.700, 0.176, 0.0
114.100, 0.176, 0.0
114.500, 0.176, 2.0
114.900, 0.176, 0.0
115.300, 0.176, 2.0
115.700, 0.176, 1.0
116.100, 0.176, 0.0
116.500, 0.176, 1.0
116.900, 0.176, 0.0
117.300, 0.176, 1.0
117.700, 0.176, 1.0
118.100, 0.176, 2.0
118.500, 0.176, 0.0
118.900, 0.176, 1.0
119.300, 0.176, 0.0
119.700, 0.176, 1.0
120.100, 0.176, 0.0
120.500, 0.176, 0.0
120.900, 0.176, 0.0
121.300, 0.176, 4.0
121.700, 0.176, 0.0
122.100, 0.176, 1.0
122.500, 0.176, 1.0
122.900, 0.176, 2.0
123.300, 0.176, 0.0
123.700, 0.176, 0.0
124.100, 0.176, 0.0
124.500, 0.176, 1.0
124.900, 0.176, 0.0
125.300, 0.176, 0.0
125.700, 0.176, 0.0
126.100, 0.176, 0.0
126.500, 0.176, 0.0
126.900, 0.176, 1.0
127.300, 0.176, 0.0
127.700, 0.176, 0.0
128.100, 0.176, 2.0
128.500, 0.176, 0.0
128.900, 0.176, 0.0
129.300, 0.176, 0.0
129.700, 0.176, 0.0
130.100, 0.176, 0.0
130.500, 0.176, 1.0
130.900, 0.176, 2.0
131.300, 0.176, 2.0
131.700, 0.176, 0.0
132.100, 0.176, 0.0
132.500, 0.176, 0.0
132.900, 0.176, 2.0
133.300, 0.176, 0.0
133.700, 0.176, 0.0
134.100, 0.176, 2.0
134.500, 0.176, 0.0
134.900, 0.176, 0.0
135.300, 0.176, 1.0
135.700, 0.176, 1.0
136.100, 0.176, 0.0
136.500, 0.176, 0.0
136.900, 0.176, 3.0
137.300, 0.176, 1.0
137.700, 0.176, 0.0
138.100, 0.176, 0.0
138.500, 0.176, 1.0
138.900, 0.176, 0.0
139.300, 0.176, 0.0
139.700, 0.176, 0.0
140.100, 0.176, 2.0
140.500, 0.176, 2.0
140.900, 0.176, 0.0
141.300, 0.176, 0.0
141.700, 0.176, 0.0
142.100, 0.176, 0.0
142.500, 0.176, 0.0
142.900, 0.176, 3.0
143.300, 0.176, 0.0
143.700, 0.176, 1.0
144.100, 0.176, 2.0
144.500, 0.176, 0.0
144.900, 0.176, 1.0
145.300, 0.176, 0.0
145.700, 0.176, 1.0
146.100, 0.176, 0.0
146.500, 0.176, 1.0
146.900, 0.176, 0.0
147.300, 0.176, 0.0
147.700, 0.176, 2.0
148.100, 0.176, 0.0
148.500, 0.176, 0.0
148.900, 0.176, 0.0
149.300, 0.176, 1.0
149.700, 0.176, 0.0
150.100, 0.176, 1.0
150.500, 0.176, 1.0
150.900, 0.176, 1.0
151.300, 0.176, 1.0
151.700, 0.176, 0.0
152.100, 0.176, 1.0
152.500, 0.176, 0.0
152.900, 0.176, 0.0
153.300, 0.176, 0.0
153.700, 0.176, 1.0
154.100, 0.176, 0.0
154.500, 0.176, 2.0
154.900, 0.176, 1.0
155.300, 0.176, 1.0
155.700, 0.176, 1.0
156.100, 0.176, 1.0
156.500, 0.176, 0.0
156.900, 0.176, 1.0
157.300, 0.176, 2.0
157.700, 0.176, 1.0
158.100, 0.176, 0.0
158.500, 0.176, 1.0
158.900, 0.176, 1.0
159.300, 0.176, 2.0
159.700, 0.176, 1.0
160.100, 0.176, 1.0
160.500, 0.176, 1.0
160.900, 0.176, 1.0
161.300, 0.176, 3.0
161.700, 0.176, 3.0
162.100, 0.176, 2.0
162.500, 0.176, 2.0
162.900, 0.176, 0.0
163.300, 0.176, 1.0
163.700, 0.176, 0.0
164.100, 0.176, 5.0
164.500, 0.176, 0.0
164.900, 0.176, 2.0
165.300, 0.176, 0.0
165.700, 0.176, 3.0
166.100, 0.176, 2.0
166.500, 0.176, 2.0
166.900, 0.176, 3.0
167.300, 0.176, 2.0
167.700, 0.176, 2.0
168.100, 0.176, 3.0
168.500, 0.176, 5.0
168.900, 0.176, 6.0
169.300, 0.176, 6.0
169.700, 0.176, 5.0
170.100, 0.176, 8.0
170.500, 0.176, 9.0
170.900, 0.176, 4.0
171.300, 0.176, 8.0
171.700, 0.176, 8.0
172.100, 0.176, 14.0
172.500, 0.176, 22.0
172.900, 0.176, 29.0
173.300, 0.176, 84.0
173.700, 0.176, 5057.0
174.100, 0.176, 3801.0
174.500, 0.176, 33.0
174.900, 0.176, 22.0
175.300, 0.176, 16.0
175.700, 0.176, 13.0
176.100, 0.176, 10.0
176.500, 0.176, 9.0
176.900, 0.176, 10.0
177.300, 0.176, 8.0
177.700, 0.176, 6.0
178.100, 0.176, 2.0
178.500, 0.176, 3.0
178.900, 0.176, 6.0
179.300, 0.176, 2.0
179.700, 0.176, 7.0
180.100, 0.176, 4.0
180.500, 0.176, 3.0
180.900, 0.176, 3.0
181.300, 0.176, 1.0
181.700, 0.176, 1.0
182.100, 0.176, 3.0
182.500, 0.176, 0.0
182.900, 0.176, 2.0
183.300, 0.176, 0.0
183.700, 0.176, 4.0
184.100, 0.176, 0.0
184.500, 0.176, 3.0
184.900, 0.176, 3.0
185.300, 0.176, 3.0
185.700, 0.176, 1.0
186.100, 0.176, 0.0
186.500, 0.176, 2.0
186.900, 0.176, 5.0
187.300, 0.176, 1.0
187.700, 0.176, 1.0
188.100, 0.176, 1.0
188.500, 0.176, 2.0
188.900, 0.176, 1.0
189.300, 0.176, 2.0
189.700, 0.176, 2.0
190.100, 0.176, 1.0
190.500, 0.176, 0.0
190.900, 0.176, 0.0
191.300, 0.176, 1.0
191.700, 0.176, 1.0
192.100, 0.176, 1.0
192.500, 0.176, 1.0
192.900, 0.176, 1.0
193.300, 0.176, 2.0
193.700, 0.176, 0.0
194.100, 0.176, 0.0
194.500, 0.176, 0.0
194.900, 0.176, 0.0
195.300, 0.176, 1.0
195.700, 0.176, 1.0
196.100, 0.176, 0.0
196.500, 0.176, 1.0
196.900, 0.176, 0.0
197.300, 0.176, 0.0
197.700, 0.176, 2.0
198.100, 0.176, 0.0
198.500, 0.176, 1.0
198.900, 0.176, 0.0
199.300, 0.176, 0.0
199.700, 0.176, 0.0
200.100, 0.176, 2.0
200.500, 0.176, 2.0
200.900, 0.176, 0.0
201.300, 0.176, 0.0
201.700, 0.176, 0.0
202.100, 0.176, 2.0
202.500, 0.176, 2.0
202.900, 0.176, 1.0
203.300, 0.176, 0.0
203.700, 0.176, 0.0
204.100, 0.176, 1.0
204.500, 0.176, 1.0
204.900, 0.176, 1.0
205.300, 0.176, 0.0
205.700, 0.176, 1.0
206.100, 0.176, 2.0
206.500, 0.176, 0.0
206.900, 0.176, 1.0
207.300, 0.176, 0.0
207.700, 0.176, 0.0
208.100, 0.176, 0.0
208.500, 0.176, 0.0
208.900, 0.176, 0.0
209.300, 0.176, 3.0
209.700, 0.176, 0.0
210.100, 0.176, 0.0
210.500, 0.176, 2.0
210.900, 0.176, 2.0
211.300, 0.176, 1.0
211.700, 0.176, 1.0
212.100, 0.176, 0.0
212.500, 0.176, 0.0
212.900, 0.176, 1.0
213.300, 0.176, 1.0
213.700, 0.176, 3.0
214.100, 0.176, 0.0
214.500, 0.176, 0.0
214.900, 0.176, 0.0
215.300, 0.176, 0.0
215.700, 0.176, 1.0
216.100, 0.176, 0.0
216.500, 0.176, 1.0
216.900, 0.176, 1.0
217.300, 0.176, 0.0
217.700, 0.176, 0.0
218.100, 0.176, 0.0
218.500, 0.176, 0.0
218.900, 0.176, 0.0
219.300, 0.176, 0.0
219.700, 0.176, 1.0
220.100, 0.176, 0.0
220.500, 0.176, 0.0
220.900, 0.176, 1.0
221.300, 0.176, 0.0
221.700, 0.176, 0.0
222.100, 0.176, 0.0
222.500, 0.176, 2.0
222.900, 0.176, 0.0
223.300, 0.176, 0.0
223.700, 0.176, 1.0
224.100, 0.176, 0.0
224.500, 0.176, 0.0
224.900, 0.176, 0.0
225.300, 0.176, 0.0
225.700, 0.176, 0.0
226.100, 0.176, 2.0
226.500, 0.176, 1.0
226.900, 0.176, 0.0
227.300, 0.176, 2.0
227.700, 0.176, 0.0
228.100, 0.176, 3.0
228.500, 0.176, 0.0
228.900, 0.176, 2.0
229.300, 0.176, 0.0
229.700, 0.176, 0.0
230.100, 0.176, 1.0
230.500, 0.176, 2.0
230.900, 0.176, 0.0
231.300, 0.176, 1.0
231.700, 0.176, 0.0
232.100, 0.176, 1.0
232.500, 0.176, 1.0
232.900, 0.176, 0.0
233.300, 0.176, 0.0
233.700, 0.176, 0.0
234.100, 0.176, 2.0
234.500, 0.176, 0.0
234.900, 0.176, 1.0
235.300, 0.176, 2.0
235.700, 0.176, 2.0
236.100, 0.176, 3.0
236.500, 0.176, 2.0
236.900, 0.176, 1.0
237.300, 0.176, 0.0
237.700, 0.176, 2.0
238.100, 0.176, 0.0
238.500, 0.176, 0.0
238.900, 0.176, 3.0
239.300, 0.176, 2.0
239.700, 0.176, 1.0
240.100, 0.176, 0.0
240.500, 0.176, 0.0
240.900, 0.176, 0.0
241.300, 0.176, 0.0
241.700, 0.176, 0.0
242.100, 0.176, 1.0
242.500, 0.176, 1.0
242.900, 0.176, 0.0
243.300, 0.176, 1.0
243.700, 0.176, 1.0
244.100, 0.176, 2.0
244.500, 0.176, 0.0
244.900, 0.176, 0.0
245.300, 0.176, 1.0
245.700, 0.176, 1.0
246.100, 0.176, 1.0
246.500, 0.176, 0.0
246.900, 0.176, 0.0
247.300, 0.176, 1.0
247.700, 0.176, 1.0
248.100, 0.176, 4.0
248.500, 0.176, 2.0
248.900, 0.176, 0.0
249.300, 0.176, 0.0
249.700, 0.176, 1.0
250.100, 0.176, 1.0
250.500, 0.176, 2.0
250.900, 0.176, 0.0
251.300, 0.176, 2.0
251.700, 0.176, 3.0
252.100, 0.176, 1.0
252.500, 0.176, 2.0
252.900, 0.176, 1.0
253.300, 0.176, 4.0
253.700, 0.176, 4.0
254.100, 0.176, 3.0
254.500, 0.176, 3.0
254.900, 0.176, 3.0
255.300, 0.176, 0.0
255.700, 0.176, 5.0
256.100, 0.176, 3.0
256.500, 0.176, 1.0
256.900, 0.176, 3.0
257.300, 0.176, 0.0
257.700, 0.176, 2.0
258.100, 0.176, 5.0
258.500, 0.176, 2.0
258.900, 0.176, 4.0
259.300, 0.176, 6.0
259.700, 0.176, 5.0
260.100, 0.176, 3.0
260.500, 0.176, 7.0
260.900, 0.176, 6.0
261.300, 0.176, 4.0
261.700, 0.176, 10.0
262.100, 0.176, 11.0
262.500, 0.176, 6.0
262.900, 0.176, 15.0
263.300, 0.176, 8.0
263.700, 0.176, 25.0
264.100, 0.176, 85.0
264.500, 0.176, 6655.0
264.900, 0.176, 2498.0
265.300, 0.176, 19.0
265.700, 0.176, 15.0
266.100, 0.176, 12.0
266.500, 0.176, 6.0
266.900, 0.176, 9.0
267.300, 0.176, 5.0
267.700, 0.176, 6.0
268.100, 0.176, 7.0
268.500, 0.176, 2.0
268.900, 0.176, 2.0
269.300, 0.176, 1.0
269.700, 0.176, 4.0
270.100, 0.176, 2.0
270.500, 0.176, 2.0
270.900, 0.176, 4.0
271.300, 0.176, 4.0
271.700, 0.176, 1.0
272.100, 0.176, 5.0
272.500, 0.176, 6.0
272.900, 0.176, 2.0
273.300, 0.176, 0.0
273.700, 0.176, 3.0
274.100, 0.176, 1.0
274.500, 0.176, 3.0
274.900, 0.176, 2.0
275.300, 0.176, 2.0
275.700, 0.176, 0.0
276.100, 0.176, 0.0
276.500, 0.176, 2.0
276.900, 0.176, 0.0
277.300, 0.176, 0.0
277.700, 0.176, 1.0
278.100, 0.176, 3.0
278.500, 0.176, 1.0
278.900, 0.176, 1.0
279.300, 0.176, 1.0
279.700, 0.176, 0.0
280.100, 0.176, 1.0
280.500, 0.176, 1.0
280.900, 0.176, 3.0
281.300, 0.176, 3.0
281.700, 0.176, 0.0
282.100, 0.176, 1.0
282.500, 0.176, 2.0
282.900, 0.176, 1.0
283.300, 0.176, 1.0
283.700, 0.176, 2.0
284.100, 0.176, 1.0
284.500, 0.176, 1.0
284.900, 0.176, 1.0
285.300, 0.176, 0.0
285.700, 0.176, 2.0
286.100, 0.176, 0.0
286.500, 0.176, 0.0
286.900, 0.176, 3.0
287.300, 0.176, 0.0
287.700, 0.176, 0.0
288.100, 0.176, 1.0
288.500, 0.176, 1.0
288.900, 0.176, 2.0
289.300, 0.176, 0.0
289.700, 0.176, 1.0
290.100, 0.176, 1.0
290.500, 0.176, 0.0
290.900, 0.176, 0.0
291.300, 0.176, 0.0
291.700, 0.176, 0.0
292.100, 0.176, 1.0
292.500, 0.176, 0.0
292.900, 0.176, 1.0
293.300, 0.176, 0.0
293.700, 0.176, 1.0
294.100, 0.176, 0.0
294.500, 0.176, 0.0
294.900, 0.176, 1.0
295.300, 0.176, 0.0
295.700, 0.176, 2.0
296.100, 0.176, 2.0
296.500, 0.176, 0.0
296.900, 0.176, 0.0
297.300, 0.176, 0.0
297.700, 0.176, 0.0
298.100, 0.176, 0.0
298.500, 0.176, 1.0
298.900, 0.176, 2.0
299.300, 0.176, 2.0
299.700, 0.176, 1.0
300.100, 0.176, 0.0
300.500, 0.176, 1.0
300.900, 0.176, 1.0
301.300, 0.176, 0.0
301.700, 0.176, 0.0
302.100, 0.176, 2.0
302.500, 0.176, 0.0
302.900, 0.176, 1.0
303.300, 0.176, 1.0
303.700, 0.176, 1.0
304.100, 0.176, 0.0
304.500, 0.176, 1.0
304.900, 0.176, 0.0
305.300, 0.176, 1.0
305.700, 0.176, 1.0
306.100, 0.176, 0.0
306.500, 0.176, 0.0
306.900, 0.176, 0.0
307.300, 0.176, 0.0
307.700, 0.176, 4.0
308.100, 0.176, 0.0
308.500, 0.176, 0.0
308.900, 0.176, 1.0
309.300, 0.176, 1.0
309.700, 0.176, 0.0
310.100, 0.176, 0.0
310.500, 0.176, 0.0
310.900, 0.176, 1.0
311.300, 0.176, 0.0
311.700, 0.176, 0.0
312.100, 0.176, 0.0
312.500, 0.176, 0.0
312.900, 0.176, 0.0
313.300, 0.176, 2.0
313.700, 0.176, 0.0
314.100, 0.176, 1.0
314.500, 0.176, 1.0
314.900, 0.176, 0.0
315.300, 0.176, 2.0
315.700, 0.176, 0.0
316.100, 0.176, 0.0
316.500, 0.176, 0.0
316.900, 0.176, 0.0
317.300, 0.176, 0.0
317.700, 0.176, 0.0
318.100, 0.176, 0.0
318.500, 0.176, 1.0
318.900, 0.176, 1.0
319.300, 0.176, 0.0
319.700, 0.176, 1.0
320.100, 0.176, 0.0
320.500, 0.176, 0.0
320.900, 0.176, 0.0
321.300, 0.176, 0.0
321.700, 0.176, 0.0
322.100, 0.176, 0.0
322.500, 0.176, 0.0
322.900, 0.176, 1.0
323.300, 0.176, 0.0
323.700, 0.176, 1.0
324.100, 0.176, 0.0
324.500, 0.176, 0.0
324.900, 0.176, 0.0
325.300, 0.176, 1.0
325.700, 0.176, 3.0
326.100, 0.176, 2.0
326.500, 0.176, 0.0
326.900, 0.176, 0.0
327.300, 0.176, 2.0
327.700, 0.176, 1.0
328.100, 0.176, 0.0
328.500, 0.176, 4.0
328.900, 0.176, 2.0
329.300, 0.176, 1.0
329.700, 0.176, 1.0
330.100, 0.176, 1.0
330.500, 0.176, 0.0
330.900, 0.176, 1.0
331.300, 0.176, 0.0
331.700, 0.176, 1.0
332.100, 0.176, 0.0
332.500, 0.176, 1.0
332.900, 0.176, 2.0
333.300, 0.176, 1.0
333.700, 0.176, 1.0
334.100, 0.176, 0.0
334.500, 0.176, 3.0
334.900, 0.176, 0.0
335.300, 0.176, 1.0
335.700, 0.176, 0.0
336.100, 0.176, 0.0
336.500, 0.176, 1.0
336.900, 0.176, 0.0
337.300, 0.176, 0.0
337.700, 0.176, 1.0
338.100, 0.176, 2.0
338.500, 0.176, 1.0
338.900, 0.176, 1.0
339.300, 0.176, 2.0
339.700, 0.176, 0.0
340.100, 0.176, 3.0
340.500, 0.176, 0.0
340.900, 0.176, 2.0
341.300, 0.176, 0.0
341.700, 0.176, 3.0
342.100, 0.176, 1.0
342.500, 0.176, 2.0
342.900, 0.176, 0.0
343.300, 0.176, 2.0
343.700, 0.176, 2.0
344.100, 0.176, 1.0
344.500, 0.176, 3.0
344.900, 0.176, 0.0
345.300, 0.176, 3.0
345.700, 0.176, 2.0
346.100, 0.176, 2.0
346.500, 0.176, 0.0
346.900, 0.176, 1.0
347.300, 0.176, 1.0
347.700, 0.176, 4.0
348.100, 0.176, 1.0
348.500, 0.176, 2.0
348.900, 0.176, 1.0
349.300, 0.176, 0.0
349.700, 0.176, 2.0
350.100, 0.176, 1.0
350.500, 0.176, 3.0
350.900, 0.176, 6.0
351.300, 0.176, 9.0
351.700, 0.176, 5.0
352.100, 0.176, 8.0
352.500, 0.176, 10.0
352.900, 0.176, 7.0
353.300, 0.176, 11.0
353.700, 0.176, 5.0
354.100, 0.176, 26.0
354.500, 0.176, 78.0
354.900, 0.176, 5986.0
355.300, 0.176, 2027.0
355.700, 0.176, 29.0
356.100, 0.176, 19.0
356.500, 0.176, 15.0
356.900, 0.176, 14.0
357.300, 0.176, 9.0
357.700, 0.176, 4.0
358.100, 0.176, 4.0
358.500, 0.176, 8.0
358.900, 0.176, 4.0
359.300, 0.176, 5.0
359.700, 0.176, 8.0
359.900, 0.176, 5.0