File: Data/Figure3/MAPbBr3-powder-gonio.csv
[Measurement conditions]
Sample identification,
Comment - 1,"Configuration=Sample Spinner (Reflection-Transmission), Owner=User-1, Creation date=11/23/2015 8:19:59 AM"
Comment - 2,"Goniometer=Theta/Theta; Minimum step size 2Theta:0.0001; Minimum step size Omega:0.0001"
Comment - 3,"Sample stage=Reflection-transmission spinner; Minimum step size Phi:0.1"
Comment - 4,"Diffractometer system=EMPYREAN"
Comment - 5,"Measurement program=C:\PANalytical\Data Collector\Programs\Yuki spinner 10-70.xrdmp, Identifier={A35A966D-632C-4F63-8C54-904912ED7E1C}"
Anode material,Cu
K-Alpha1 wavelength,1.5405980
K-Alpha2 wavelength,1.5444260
Ratio K-Alpha2/K-Alpha1,0.500
Divergence slit,Fixed,0.19mm
Monochromator used,NO
Generator voltage, 45
Tube current, 40
File date and time,27/Jun/2023 09:52
Unit cell,
h k l, 0 0 0
Scan axis,Gonio
Scan range,9.994599997,69.999991833
Scan step size,0.0262606
No. of points, 2285
Scan type,CONTINUOUS
Phi,219.8
Time per step,22.440
[Scan points]
Angle, TimePerStep, Intensity
10.007730280, 22.440, 148.0
10.060251411, 22.440, 167.0
10.112772541, 22.440, 160.0
10.165293672, 22.440, 154.0
10.217814803, 22.440, 154.0
10.270335934, 22.440, 168.0
10.322857064, 22.440, 138.0
10.375378195, 22.440, 180.0
10.427899326, 22.440, 156.0
10.480420456, 22.440, 162.0
10.532941587, 22.440, 172.0
10.585462718, 22.440, 167.0
10.637983849, 22.440, 142.0
10.690504979, 22.440, 149.0
10.743026110, 22.440, 150.0
10.795547241, 22.440, 151.0
10.848068371, 22.440, 155.0
10.900589502, 22.440, 159.0
10.953110633, 22.440, 140.0
11.005631763, 22.440, 134.0
11.058152894, 22.440, 123.0
11.110674025, 22.440, 162.0
11.163195156, 22.440, 128.0
11.215716286, 22.440, 152.0
11.268237417, 22.440, 148.0
11.320758548, 22.440, 143.0
11.373279678, 22.440, 156.0
11.425800809, 22.440, 151.0
11.478321940, 22.440, 147.0
11.530843071, 22.440, 128.0
11.583364201, 22.440, 130.0
11.635885332, 22.440, 149.0
11.688406463, 22.440, 115.0
11.740927593, 22.440, 128.0
11.793448724, 22.440, 147.0
11.845969855, 22.440, 143.0
11.898490986, 22.440, 138.0
11.951012116, 22.440, 149.0
12.003533247, 22.440, 142.0
12.056054378, 22.440, 122.0
12.108575508, 22.440, 138.0
12.161096639, 22.440, 125.0
12.213617770, 22.440, 138.0
12.266138900, 22.440, 128.0
12.318660031, 22.440, 125.0
12.371181162, 22.440, 120.0
12.423702293, 22.440, 149.0
12.476223423, 22.440, 111.0
12.528744554, 22.440, 135.0
12.581265685, 22.440, 133.0
12.633786815, 22.440, 114.0
12.686307946, 22.440, 109.0
12.738829077, 22.440, 129.0
12.791350208, 22.440, 132.0
12.843871338, 22.440, 159.0
12.896392469, 22.440, 133.0
12.948913600, 22.440, 125.0
13.001434730, 22.440, 102.0
13.053955861, 22.440, 101.0
13.106476992, 22.440, 115.0
13.158998123, 22.440, 102.0
13.211519253, 22.440, 111.0
13.264040384, 22.440, 125.0
13.316561515, 22.440, 117.0
13.369082645, 22.440, 124.0
13.421603776, 22.440, 106.0
13.474124907, 22.440, 131.0
13.526646038, 22.440, 110.0
13.579167168, 22.440, 87.0
13.631688299, 22.440, 119.0
13.684209430, 22.440, 118.0
13.736730560, 22.440, 98.0
13.789251691, 22.440, 112.0
13.841772822, 22.440, 115.0
13.894293952, 22.440, 114.0
13.946815083, 22.440, 109.0
13.999336214, 22.440, 99.0
14.051857345, 22.440, 102.0
14.104378475, 22.440, 99.0
14.156899606, 22.440, 106.0
14.209420737, 22.440, 104.0
14.261941867, 22.440, 101.0
14.314462998, 22.440, 118.0
14.366984129, 22.440, 84.0
14.419505260, 22.440, 105.0
14.472026390, 22.440, 88.0
14.524547521, 22.440, 111.0
14.577068652, 22.440, 109.0
14.629589782, 22.440, 108.0
14.682110913, 22.440, 120.0
14.734632044, 22.440, 106.0
14.787153175, 22.440, 135.0
14.839674305, 22.440, 110.0
14.892195436, 22.440, 145.0
14.944716567, 22.440, 215.0
14.997237697, 22.440, 239.0
15.049758828, 22.440, 350.0
15.102279959, 22.440, 855.0
15.154801090, 22.440, 1664.0
15.207322220, 22.440, 2009.0
15.259843351, 22.440, 1225.0
15.312364482, 22.440, 640.0
15.364885612, 22.440, 203.0
15.417406743, 22.440, 160.0
15.469927874, 22.440, 111.0
15.522449004, 22.440, 101.0
15.574970135, 22.440, 82.0
15.627491266, 22.440, 99.0
15.680012397, 22.440, 90.0
15.732533527, 22.440, 92.0
15.785054658, 22.440, 83.0
15.837575789, 22.440, 104.0
15.890096919, 22.440, 83.0
15.942618050, 22.440, 78.0
15.995139181, 22.440, 97.0
16.047660312, 22.440, 75.0
16.100181442, 22.440, 70.0
16.152702573, 22.440, 89.0
16.205223704, 22.440, 87.0
16.257744834, 22.440, 74.0
16.310265965, 22.440, 94.0
16.362787096, 22.440, 68.0
16.415308227, 22.440, 89.0
16.467829357, 22.440, 85.0
16.520350488, 22.440, 101.0
16.572871619, 22.440, 83.0
16.625392749, 22.440, 104.0
16.677913880, 22.440, 88.0
16.730435011, 22.440, 81.0
16.782956141, 22.440, 71.0
16.835477272, 22.440, 90.0
16.887998403, 22.440, 85.0
16.940519534, 22.440, 95.0
16.993040664, 22.440, 95.0
17.045561795, 22.440, 82.0
17.098082926, 22.440, 79.0
17.150604056, 22.440, 90.0
17.203125187, 22.440, 84.0
17.255646318, 22.440, 75.0
17.308167449, 22.440, 97.0
17.360688579, 22.440, 73.0
17.413209710, 22.440, 76.0
17.465730841, 22.440, 68.0
17.518251971, 22.440, 87.0
17.570773102, 22.440, 65.0
17.623294233, 22.440, 82.0
17.675815364, 22.440, 74.0
17.728336494, 22.440, 91.0
17.780857625, 22.440, 71.0
17.833378756, 22.440, 71.0
17.885899886, 22.440, 70.0
17.938421017, 22.440, 66.0
17.990942148, 22.440, 77.0
18.043463279, 22.440, 69.0
18.095984409, 22.440, 71.0
18.148505540, 22.440, 79.0
18.201026671, 22.440, 62.0
18.253547801, 22.440, 65.0
18.306068932, 22.440, 71.0
18.358590063, 22.440, 73.0
18.411111193, 22.440, 64.0
18.463632324, 22.440, 66.0
18.516153455, 22.440, 68.0
18.568674586, 22.440, 80.0
18.621195716, 22.440, 54.0
18.673716847, 22.440, 59.0
18.726237978, 22.440, 57.0
18.778759108, 22.440, 59.0
18.831280239, 22.440, 69.0
18.883801370, 22.440, 81.0
18.936322501, 22.440, 57.0
18.988843631, 22.440, 66.0
19.041364762, 22.440, 75.0
19.093885893, 22.440, 64.0
19.146407023, 22.440, 66.0
19.198928154, 22.440, 55.0
19.251449285, 22.440, 75.0
19.303970416, 22.440, 71.0
19.356491546, 22.440, 51.0
19.409012677, 22.440, 62.0
19.461533808, 22.440, 72.0
19.514054938, 22.440, 75.0
19.566576069, 22.440, 77.0
19.619097200, 22.440, 60.0
19.671618331, 22.440, 62.0
19.724139461, 22.440, 57.0
19.776660592, 22.440, 62.0
19.829181723, 22.440, 71.0
19.881702853, 22.440, 64.0
19.934223984, 22.440, 69.0
19.986745115, 22.440, 57.0
20.039266245, 22.440, 56.0
20.091787376, 22.440, 58.0
20.144308507, 22.440, 56.0
20.196829638, 22.440, 60.0
20.249350768, 22.440, 62.0
20.301871899, 22.440, 59.0
20.354393030, 22.440, 55.0
20.406914160, 22.440, 62.0
20.459435291, 22.440, 67.0
20.511956422, 22.440, 64.0
20.564477553, 22.440, 52.0
20.616998683, 22.440, 60.0
20.669519814, 22.440, 60.0
20.722040945, 22.440, 56.0
20.774562075, 22.440, 70.0
20.827083206, 22.440, 60.0
20.879604337, 22.440, 69.0
20.932125468, 22.440, 62.0
20.984646598, 22.440, 70.0
21.037167729, 22.440, 54.0
21.089688860, 22.440, 74.0
21.142209990, 22.440, 59.0
21.194731121, 22.440, 66.0
21.247252252, 22.440, 100.0
21.299773382, 22.440, 144.0
21.352294513, 22.440, 284.0
21.404815644, 22.440, 460.0
21.457336775, 22.440, 903.0
21.509857905, 22.440, 588.0
21.562379036, 22.440, 248.0
21.614900167, 22.440, 117.0
21.667421297, 22.440, 88.0
21.719942428, 22.440, 59.0
21.772463559, 22.440, 62.0
21.824984690, 22.440, 61.0
21.877505820, 22.440, 51.0
21.930026951, 22.440, 56.0
21.982548082, 22.440, 41.0
22.035069212, 22.440, 48.0
22.087590343, 22.440, 44.0
22.140111474, 22.440, 61.0
22.192632605, 22.440, 68.0
22.245153735, 22.440, 57.0
22.297674866, 22.440, 50.0
22.350195997, 22.440, 47.0
22.402717127, 22.440, 45.0
22.455238258, 22.440, 50.0
22.507759389, 22.440, 53.0
22.560280520, 22.440, 53.0
22.612801650, 22.440, 54.0
22.665322781, 22.440, 38.0
22.717843912, 22.440, 44.0
22.770365042, 22.440, 53.0
22.822886173, 22.440, 47.0
22.875407304, 22.440, 47.0
22.927928434, 22.440, 50.0
22.980449565, 22.440, 47.0
23.032970696, 22.440, 53.0
23.085491827, 22.440, 59.0
23.138012957, 22.440, 46.0
23.190534088, 22.440, 47.0
23.243055219, 22.440, 59.0
23.295576349, 22.440, 45.0
23.348097480, 22.440, 47.0
23.400618611, 22.440, 44.0
23.453139742, 22.440, 57.0
23.505660872, 22.440, 42.0
23.558182003, 22.440, 45.0
23.610703134, 22.440, 49.0
23.663224264, 22.440, 51.0
23.715745395, 22.440, 44.0
23.768266526, 22.440, 52.0
23.820787657, 22.440, 51.0
23.873308787, 22.440, 49.0
23.925829918, 22.440, 39.0
23.978351049, 22.440, 48.0
24.030872179, 22.440, 52.0
24.083393310, 22.440, 50.0
24.135914441, 22.440, 52.0
24.188435572, 22.440, 55.0
24.240956702, 22.440, 52.0
24.293477833, 22.440, 47.0
24.345998964, 22.440, 55.0
24.398520094, 22.440, 52.0
24.451041225, 22.440, 55.0
24.503562356, 22.440, 42.0
24.556083486, 22.440, 57.0
24.608604617, 22.440, 43.0
24.661125748, 22.440, 44.0
24.713646879, 22.440, 55.0
24.766168009, 22.440, 40.0
24.818689140, 22.440, 51.0
24.871210271, 22.440, 43.0
24.923731401, 22.440, 55.0
24.976252532, 22.440, 42.0
25.028773663, 22.440, 51.0
25.081294794, 22.440, 50.0
25.133815924, 22.440, 54.0
25.186337055, 22.440, 53.0
25.238858186, 22.440, 38.0
25.291379316, 22.440, 45.0
25.343900447, 22.440, 50.0
25.396421578, 22.440, 58.0
25.448942709, 22.440, 47.0
25.501463839, 22.440, 52.0
25.553984970, 22.440, 39.0
25.606506101, 22.440, 55.0
25.659027231, 22.440, 47.0
25.711548362, 22.440, 65.0
25.764069493, 22.440, 58.0
25.816590623, 22.440, 63.0
25.869111754, 22.440, 46.0
25.921632885, 22.440, 40.0
25.974154016, 22.440, 46.0
26.026675146, 22.440, 34.0
26.079196277, 22.440, 52.0
26.131717408, 22.440, 47.0
26.184238538, 22.440, 54.0
26.236759669, 22.440, 74.0
26.289280800, 22.440, 79.0
26.341801931, 22.440, 65.0
26.394323061, 22.440, 56.0
26.446844192, 22.440, 51.0
26.499365323, 22.440, 41.0
26.551886453, 22.440, 37.0
26.604407584, 22.440, 57.0
26.656928715, 22.440, 52.0
26.709449846, 22.440, 49.0
26.761970976, 22.440, 38.0
26.814492107, 22.440, 34.0
26.867013238, 22.440, 46.0
26.919534368, 22.440, 38.0
26.972055499, 22.440, 41.0
27.024576630, 22.440, 46.0
27.077097761, 22.440, 36.0
27.129618891, 22.440, 39.0
27.182140022, 22.440, 35.0
27.234661153, 22.440, 46.0
27.287182283, 22.440, 35.0
27.339703414, 22.440, 42.0
27.392224545, 22.440, 48.0
27.444745675, 22.440, 49.0
27.497266806, 22.440, 55.0
27.549787937, 22.440, 39.0
27.602309068, 22.440, 50.0
27.654830198, 22.440, 48.0
27.707351329, 22.440, 43.0
27.759872460, 22.440, 28.0
27.812393590, 22.440, 51.0
27.864914721, 22.440, 29.0
27.917435852, 22.440, 54.0
27.969956983, 22.440, 26.0
28.022478113, 22.440, 49.0
28.074999244, 22.440, 46.0
28.127520375, 22.440, 42.0
28.180041505, 22.440, 41.0
28.232562636, 22.440, 48.0
28.285083767, 22.440, 43.0
28.337604898, 22.440, 36.0
28.390126028, 22.440, 27.0
28.442647159, 22.440, 30.0
28.495168290, 22.440, 38.0
28.547689420, 22.440, 50.0
28.600210551, 22.440, 49.0
28.652731682, 22.440, 38.0
28.705252813, 22.440, 36.0
28.757773943, 22.440, 40.0
28.810295074, 22.440, 26.0
28.862816205, 22.440, 37.0
28.915337335, 22.440, 50.0
28.967858466, 22.440, 51.0
29.020379597, 22.440, 58.0
29.072900727, 22.440, 51.0
29.125421858, 22.440, 55.0
29.177942989, 22.440, 59.0
29.230464120, 22.440, 51.0
29.282985250, 22.440, 50.0
29.335506381, 22.440, 48.0
29.388027512, 22.440, 40.0
29.440548642, 22.440, 55.0
29.493069773, 22.440, 52.0
29.545590904, 22.440, 58.0
29.598112035, 22.440, 48.0
29.650633165, 22.440, 46.0
29.703154296, 22.440, 45.0
29.755675427, 22.440, 56.0
29.808196557, 22.440, 52.0
29.860717688, 22.440, 47.0
29.913238819, 22.440, 48.0
29.965759950, 22.440, 50.0
30.018281080, 22.440, 50.0
30.070802211, 22.440, 76.0
30.123323342, 22.440, 75.0
30.175844472, 22.440, 142.0
30.228365603, 22.440, 209.0
30.280886734, 22.440, 325.0
30.333407864, 22.440, 966.0
30.385928995, 22.440, 1335.0
30.438450126, 22.440, 3429.0
30.490971257, 22.440, 1520.0
30.543492387, 22.440, 980.0
30.596013518, 22.440, 233.0
30.648534649, 22.440, 115.0
30.701055779, 22.440, 79.0
30.753576910, 22.440, 68.0
30.806098041, 22.440, 44.0
30.858619172, 22.440, 49.0
30.911140302, 22.440, 52.0
30.963661433, 22.440, 37.0
31.016182564, 22.440, 32.0
31.068703694, 22.440, 50.0
31.121224825, 22.440, 38.0
31.173745956, 22.440, 43.0
31.226267087, 22.440, 48.0
31.278788217, 22.440, 32.0
31.331309348, 22.440, 48.0
31.383830479, 22.440, 46.0
31.436351609, 22.440, 34.0
31.488872740, 22.440, 31.0
31.541393871, 22.440, 50.0
31.593915002, 22.440, 53.0
31.646436132, 22.440, 34.0
31.698957263, 22.440, 40.0
31.751478394, 22.440, 51.0
31.803999524, 22.440, 35.0
31.856520655, 22.440, 46.0
31.909041786, 22.440, 40.0
31.961562916, 22.440, 31.0
32.014084047, 22.440, 35.0
32.066605178, 22.440, 44.0
32.119126309, 22.440, 36.0
32.171647439, 22.440, 32.0
32.224168570, 22.440, 46.0
32.276689701, 22.440, 50.0
32.329210831, 22.440, 41.0
32.381731962, 22.440, 49.0
32.434253093, 22.440, 57.0
32.486774224, 22.440, 29.0
32.539295354, 22.440, 48.0
32.591816485, 22.440, 47.0
32.644337616, 22.440, 39.0
32.696858746, 22.440, 45.0
32.749379877, 22.440, 40.0
32.801901008, 22.440, 39.0
32.854422139, 22.440, 66.0
32.906943269, 22.440, 42.0
32.959464400, 22.440, 55.0
33.011985531, 22.440, 26.0
33.064506661, 22.440, 47.0
33.117027792, 22.440, 38.0
33.169548923, 22.440, 51.0
33.222070054, 22.440, 42.0
33.274591184, 22.440, 46.0
33.327112315, 22.440, 55.0
33.379633446, 22.440, 52.0
33.432154576, 22.440, 56.0
33.484675707, 22.440, 63.0
33.537196838, 22.440, 49.0
33.589717968, 22.440, 59.0
33.642239099, 22.440, 47.0
33.694760230, 22.440, 57.0
33.747281361, 22.440, 86.0
33.799802491, 22.440, 95.0
33.852323622, 22.440, 147.0
33.904844753, 22.440, 252.0
33.957365883, 22.440, 496.0
34.009887014, 22.440, 1630.0
34.062408145, 22.440, 2776.0
34.114929276, 22.440, 1892.0
34.167450406, 22.440, 1187.0
34.219971537, 22.440, 474.0
34.272492668, 22.440, 191.0
34.325013798, 22.440, 88.0
34.377534929, 22.440, 49.0
34.430056060, 22.440, 28.0
34.482577191, 22.440, 49.0
34.535098321, 22.440, 49.0
34.587619452, 22.440, 47.0
34.640140583, 22.440, 38.0
34.692661713, 22.440, 38.0
34.745182844, 22.440, 42.0
34.797703975, 22.440, 32.0
34.850225105, 22.440, 30.0
34.902746236, 22.440, 33.0
34.955267367, 22.440, 38.0
35.007788498, 22.440, 32.0
35.060309628, 22.440, 31.0
35.112830759, 22.440, 34.0
35.165351890, 22.440, 49.0
35.217873020, 22.440, 32.0
35.270394151, 22.440, 34.0
35.322915282, 22.440, 43.0
35.375436413, 22.440, 36.0
35.427957543, 22.440, 23.0
35.480478674, 22.440, 34.0
35.532999805, 22.440, 28.0
35.585520935, 22.440, 38.0
35.638042066, 22.440, 34.0
35.690563197, 22.440, 42.0
35.743084328, 22.440, 36.0
35.795605458, 22.440, 30.0
35.848126589, 22.440, 38.0
35.900647720, 22.440, 34.0
35.953168850, 22.440, 38.0
36.005689981, 22.440, 24.0
36.058211112, 22.440, 35.0
36.110732243, 22.440, 33.0
36.163253373, 22.440, 31.0
36.215774504, 22.440, 32.0
36.268295635, 22.440, 34.0
36.320816765, 22.440, 42.0
36.373337896, 22.440, 42.0
36.425859027, 22.440, 31.0
36.478380157, 22.440, 29.0
36.530901288, 22.440, 40.0
36.583422419, 22.440, 39.0
36.635943550, 22.440, 30.0
36.688464680, 22.440, 41.0
36.740985811, 22.440, 26.0
36.793506942, 22.440, 40.0
36.846028072, 22.440, 37.0
36.898549203, 22.440, 38.0
36.951070334, 22.440, 32.0
37.003591465, 22.440, 45.0
37.056112595, 22.440, 38.0
37.108633726, 22.440, 45.0
37.161154857, 22.440, 61.0
37.213675987, 22.440, 72.0
37.266197118, 22.440, 126.0
37.318718249, 22.440, 251.0
37.371239380, 22.440, 759.0
37.423760510, 22.440, 678.0
37.476281641, 22.440, 474.0
37.528802772, 22.440, 302.0
37.581323902, 22.440, 99.0
37.633845033, 22.440, 47.0
37.686366164, 22.440, 46.0
37.738887295, 22.440, 31.0
37.791408425, 22.440, 33.0
37.843929556, 22.440, 37.0
37.896450687, 22.440, 41.0
37.948971817, 22.440, 31.0
38.001492948, 22.440, 18.0
38.054014079, 22.440, 29.0
38.106535209, 22.440, 41.0
38.159056340, 22.440, 22.0
38.211577471, 22.440, 29.0
38.264098602, 22.440, 23.0
38.316619732, 22.440, 31.0
38.369140863, 22.440, 28.0
38.421661994, 22.440, 34.0
38.474183124, 22.440, 35.0
38.526704255, 22.440, 22.0
38.579225386, 22.440, 28.0
38.631746517, 22.440, 23.0
38.684267647, 22.440, 15.0
38.736788778, 22.440, 39.0
38.789309909, 22.440, 34.0
38.841831039, 22.440, 30.0
38.894352170, 22.440, 29.0
38.946873301, 22.440, 23.0
38.999394432, 22.440, 24.0
39.051915562, 22.440, 46.0
39.104436693, 22.440, 28.0
39.156957824, 22.440, 36.0
39.209478954, 22.440, 29.0
39.262000085, 22.440, 31.0
39.314521216, 22.440, 30.0
39.367042346, 22.440, 30.0
39.419563477, 22.440, 36.0
39.472084608, 22.440, 41.0
39.524605739, 22.440, 33.0
39.577126869, 22.440, 21.0
39.629648000, 22.440, 35.0
39.682169131, 22.440, 32.0
39.734690261, 22.440, 30.0
39.787211392, 22.440, 21.0
39.839732523, 22.440, 17.0
39.892253654, 22.440, 28.0
39.944774784, 22.440, 26.0
39.997295915, 22.440, 31.0
40.049817046, 22.440, 36.0
40.102338176, 22.440, 29.0
40.154859307, 22.440, 25.0
40.207380438, 22.440, 22.0
40.259901569, 22.440, 31.0
40.312422699, 22.440, 34.0
40.364943830, 22.440, 25.0
40.417464961, 22.440, 26.0
40.469986091, 22.440, 24.0
40.522507222, 22.440, 24.0
40.575028353, 22.440, 28.0
40.627549484, 22.440, 26.0
40.680070614, 22.440, 40.0
40.732591745, 22.440, 30.0
40.785112876, 22.440, 29.0
40.837634006, 22.440, 21.0
40.890155137, 22.440, 24.0
40.942676268, 22.440, 26.0
40.995197398, 22.440, 29.0
41.047718529, 22.440, 50.0
41.100239660, 22.440, 29.0
41.152760791, 22.440, 37.0
41.205281921, 22.440, 24.0
41.257803052, 22.440, 15.0
41.310324183, 22.440, 27.0
41.362845313, 22.440, 39.0
41.415366444, 22.440, 42.0
41.467887575, 22.440, 32.0
41.520408706, 22.440, 31.0
41.572929836, 22.440, 31.0
41.625450967, 22.440, 30.0
41.677972098, 22.440, 25.0
41.730493228, 22.440, 38.0
41.783014359, 22.440, 29.0
41.835535490, 22.440, 44.0
41.888056621, 22.440, 34.0
41.940577751, 22.440, 34.0
41.993098882, 22.440, 31.0
42.045620013, 22.440, 28.0
42.098141143, 22.440, 26.0
42.150662274, 22.440, 30.0
42.203183405, 22.440, 37.0
42.255704535, 22.440, 39.0
42.308225666, 22.440, 52.0
42.360746797, 22.440, 30.0
42.413267928, 22.440, 23.0
42.465789058, 22.440, 41.0
42.518310189, 22.440, 41.0
42.570831320, 22.440, 37.0
42.623352450, 22.440, 44.0
42.675873581, 22.440, 48.0
42.728394712, 22.440, 38.0
42.780915843, 22.440, 32.0
42.833436973, 22.440, 38.0
42.885958104, 22.440, 35.0
42.938479235, 22.440, 38.0
42.991000365, 22.440, 44.0
43.043521496, 22.440, 39.0
43.096042627, 22.440, 73.0
43.148563758, 22.440, 86.0
43.201084888, 22.440, 145.0
43.253606019, 22.440, 180.0
43.306127150, 22.440, 364.0
43.358648280, 22.440, 1021.0
43.411169411, 22.440, 1516.0
43.463690542, 22.440, 860.0
43.516211673, 22.440, 804.0
43.568732803, 22.440, 376.0
43.621253934, 22.440, 130.0
43.673775065, 22.440, 81.0
43.726296195, 22.440, 53.0
43.778817326, 22.440, 52.0
43.831338457, 22.440, 48.0
43.883859587, 22.440, 40.0
43.936380718, 22.440, 44.0
43.988901849, 22.440, 52.0
44.041422980, 22.440, 40.0
44.093944110, 22.440, 34.0
44.146465241, 22.440, 47.0
44.198986372, 22.440, 40.0
44.251507502, 22.440, 34.0
44.304028633, 22.440, 34.0
44.356549764, 22.440, 34.0
44.409070895, 22.440, 45.0
44.461592025, 22.440, 34.0
44.514113156, 22.440, 41.0
44.566634287, 22.440, 40.0
44.619155417, 22.440, 39.0
44.671676548, 22.440, 31.0
44.724197679, 22.440, 44.0
44.776718810, 22.440, 35.0
44.829239940, 22.440, 39.0
44.881761071, 22.440, 41.0
44.934282202, 22.440, 33.0
44.986803332, 22.440, 49.0
45.039324463, 22.440, 35.0
45.091845594, 22.440, 44.0
45.144366725, 22.440, 49.0
45.196887855, 22.440, 35.0
45.249408986, 22.440, 31.0
45.301930117, 22.440, 46.0
45.354451247, 22.440, 44.0
45.406972378, 22.440, 36.0
45.459493509, 22.440, 31.0
45.512014639, 22.440, 45.0
45.564535770, 22.440, 50.0
45.617056901, 22.440, 41.0
45.669578032, 22.440, 45.0
45.722099162, 22.440, 43.0
45.774620293, 22.440, 43.0
45.827141424, 22.440, 49.0
45.879662554, 22.440, 70.0
45.932183685, 22.440, 70.0
45.984704816, 22.440, 131.0
46.037225947, 22.440, 252.0
46.089747077, 22.440, 552.0
46.142268208, 22.440, 905.0
46.194789339, 22.440, 814.0
46.247310469, 22.440, 522.0
46.299831600, 22.440, 469.0
46.352352731, 22.440, 185.0
46.404873862, 22.440, 86.0
46.457394992, 22.440, 68.0
46.509916123, 22.440, 49.0
46.562437254, 22.440, 41.0
46.614958384, 22.440, 36.0
46.667479515, 22.440, 42.0
46.720000646, 22.440, 44.0
46.772521776, 22.440, 50.0
46.825042907, 22.440, 42.0
46.877564038, 22.440, 46.0
46.930085169, 22.440, 37.0
46.982606299, 22.440, 37.0
47.035127430, 22.440, 25.0
47.087648561, 22.440, 42.0
47.140169691, 22.440, 52.0
47.192690822, 22.440, 35.0
47.245211953, 22.440, 22.0
47.297733084, 22.440, 23.0
47.350254214, 22.440, 44.0
47.402775345, 22.440, 35.0
47.455296476, 22.440, 35.0
47.507817606, 22.440, 47.0
47.560338737, 22.440, 32.0
47.612859868, 22.440, 29.0
47.665380999, 22.440, 38.0
47.717902129, 22.440, 25.0
47.770423260, 22.440, 47.0
47.822944391, 22.440, 36.0
47.875465521, 22.440, 38.0
47.927986652, 22.440, 30.0
47.980507783, 22.440, 26.0
48.033028914, 22.440, 33.0
48.085550044, 22.440, 22.0
48.138071175, 22.440, 36.0
48.190592306, 22.440, 35.0
48.243113436, 22.440, 41.0
48.295634567, 22.440, 26.0
48.348155698, 22.440, 23.0
48.400676828, 22.440, 39.0
48.453197959, 22.440, 42.0
48.505719090, 22.440, 42.0
48.558240221, 22.440, 43.0
48.610761351, 22.440, 61.0
48.663282482, 22.440, 55.0
48.715803613, 22.440, 165.0
48.768324743, 22.440, 447.0
48.820845874, 22.440, 248.0
48.873367005, 22.440, 159.0
48.925888136, 22.440, 190.0
48.978409266, 22.440, 72.0
49.030930397, 22.440, 42.0
49.083451528, 22.440, 35.0
49.135972658, 22.440, 33.0
49.188493789, 22.440, 34.0
49.241014920, 22.440, 20.0
49.293536051, 22.440, 32.0
49.346057181, 22.440, 23.0
49.398578312, 22.440, 35.0
49.451099443, 22.440, 26.0
49.503620573, 22.440, 34.0
49.556141704, 22.440, 41.0
49.608662835, 22.440, 31.0
49.661183966, 22.440, 33.0
49.713705096, 22.440, 29.0
49.766226227, 22.440, 38.0
49.818747358, 22.440, 23.0
49.871268488, 22.440, 40.0
49.923789619, 22.440, 27.0
49.976310750, 22.440, 27.0
50.028831880, 22.440, 34.0
50.081353011, 22.440, 32.0
50.133874142, 22.440, 35.0
50.186395273, 22.440, 26.0
50.238916403, 22.440, 40.0
50.291437534, 22.440, 28.0
50.343958665, 22.440, 29.0
50.396479795, 22.440, 20.0
50.449000926, 22.440, 20.0
50.501522057, 22.440, 22.0
50.554043188, 22.440, 31.0
50.606564318, 22.440, 27.0
50.659085449, 22.440, 21.0
50.711606580, 22.440, 18.0
50.764127710, 22.440, 24.0
50.816648841, 22.440, 31.0
50.869169972, 22.440, 23.0
50.921691103, 22.440, 31.0
50.974212233, 22.440, 34.0
51.026733364, 22.440, 35.0
51.079254495, 22.440, 30.0
51.131775625, 22.440, 33.0
51.184296756, 22.440, 28.0
51.236817887, 22.440, 28.0
51.289339017, 22.440, 36.0
51.341860148, 22.440, 44.0
51.394381279, 22.440, 33.0
51.446902410, 22.440, 42.0
51.499423540, 22.440, 29.0
51.551944671, 22.440, 32.0
51.604465802, 22.440, 23.0
51.656986932, 22.440, 27.0
51.709508063, 22.440, 34.0
51.762029194, 22.440, 25.0
51.814550325, 22.440, 30.0
51.867071455, 22.440, 40.0
51.919592586, 22.440, 34.0
51.972113717, 22.440, 38.0
52.024634847, 22.440, 30.0
52.077155978, 22.440, 35.0
52.129677109, 22.440, 25.0
52.182198240, 22.440, 30.0
52.234719370, 22.440, 25.0
52.287240501, 22.440, 29.0
52.339761632, 22.440, 27.0
52.392282762, 22.440, 29.0
52.444803893, 22.440, 25.0
52.497325024, 22.440, 25.0
52.549846155, 22.440, 32.0
52.602367285, 22.440, 25.0
52.654888416, 22.440, 45.0
52.707409547, 22.440, 28.0
52.759930677, 22.440, 28.0
52.812451808, 22.440, 30.0
52.864972939, 22.440, 25.0
52.917494069, 22.440, 26.0
52.970015200, 22.440, 27.0
53.022536331, 22.440, 31.0
53.075057462, 22.440, 28.0
53.127578592, 22.440, 22.0
53.180099723, 22.440, 24.0
53.232620854, 22.440, 30.0
53.285141984, 22.440, 28.0
53.337663115, 22.440, 23.0
53.390184246, 22.440, 49.0
53.442705377, 22.440, 25.0
53.495226507, 22.440, 30.0
53.547747638, 22.440, 38.0
53.600268769, 22.440, 46.0
53.652789899, 22.440, 103.0
53.705311030, 22.440, 159.0
53.757832161, 22.440, 216.0
53.810353292, 22.440, 152.0
53.862874422, 22.440, 132.0
53.915395553, 22.440, 118.0
53.967916684, 22.440, 61.0
54.020437814, 22.440, 52.0
54.072958945, 22.440, 38.0
54.125480076, 22.440, 32.0
54.178001207, 22.440, 44.0
54.230522337, 22.440, 30.0
54.283043468, 22.440, 27.0
54.335564599, 22.440, 29.0
54.388085729, 22.440, 35.0
54.440606860, 22.440, 32.0
54.493127991, 22.440, 30.0
54.545649121, 22.440, 19.0
54.598170252, 22.440, 31.0
54.650691383, 22.440, 32.0
54.703212514, 22.440, 34.0
54.755733644, 22.440, 45.0
54.808254775, 22.440, 30.0
54.860775906, 22.440, 32.0
54.913297036, 22.440, 27.0
54.965818167, 22.440, 32.0
55.018339298, 22.440, 26.0
55.070860429, 22.440, 24.0
55.123381559, 22.440, 30.0
55.175902690, 22.440, 35.0
55.228423821, 22.440, 26.0
55.280944951, 22.440, 36.0
55.333466082, 22.440, 36.0
55.385987213, 22.440, 40.0
55.438508344, 22.440, 33.0
55.491029474, 22.440, 33.0
55.543550605, 22.440, 28.0
55.596071736, 22.440, 27.0
55.648592866, 22.440, 29.0
55.701113997, 22.440, 34.0
55.753635128, 22.440, 34.0
55.806156258, 22.440, 38.0
55.858677389, 22.440, 39.0
55.911198520, 22.440, 46.0
55.963719651, 22.440, 62.0
56.016240781, 22.440, 108.0
56.068761912, 22.440, 192.0
56.121283043, 22.440, 653.0
56.173804173, 22.440, 481.0
56.226325304, 22.440, 179.0
56.278846435, 22.440, 220.0
56.331367566, 22.440, 132.0
56.383888696, 22.440, 65.0
56.436409827, 22.440, 34.0
56.488930958, 22.440, 38.0
56.541452088, 22.440, 41.0
56.593973219, 22.440, 41.0
56.646494350, 22.440, 25.0
56.699015481, 22.440, 35.0
56.751536611, 22.440, 28.0
56.804057742, 22.440, 25.0
56.856578873, 22.440, 38.0
56.909100003, 22.440, 31.0
56.961621134, 22.440, 38.0
57.014142265, 22.440, 25.0
57.066663396, 22.440, 29.0
57.119184526, 22.440, 33.0
57.171705657, 22.440, 36.0
57.224226788, 22.440, 33.0
57.276747918, 22.440, 25.0
57.329269049, 22.440, 28.0
57.381790180, 22.440, 35.0
57.434311310, 22.440, 30.0
57.486832441, 22.440, 15.0
57.539353572, 22.440, 32.0
57.591874703, 22.440, 38.0
57.644395833, 22.440, 39.0
57.696916964, 22.440, 36.0
57.749438095, 22.440, 28.0
57.801959225, 22.440, 32.0
57.854480356, 22.440, 33.0
57.907001487, 22.440, 39.0
57.959522618, 22.440, 27.0
58.012043748, 22.440, 28.0
58.064564879, 22.440, 34.0
58.117086010, 22.440, 34.0
58.169607140, 22.440, 45.0
58.222128271, 22.440, 48.0
58.274649402, 22.440, 82.0
58.327170533, 22.440, 127.0
58.379691663, 22.440, 148.0
58.432212794, 22.440, 258.0
58.484733925, 22.440, 184.0
58.537255055, 22.440, 128.0
58.589776186, 22.440, 141.0
58.642297317, 22.440, 93.0
58.694818448, 22.440, 47.0
58.747339578, 22.440, 33.0
58.799860709, 22.440, 37.0
58.852381840, 22.440, 29.0
58.904902970, 22.440, 29.0
58.957424101, 22.440, 24.0
59.009945232, 22.440, 21.0
59.062466362, 22.440, 24.0
59.114987493, 22.440, 38.0
59.167508624, 22.440, 24.0
59.220029755, 22.440, 27.0
59.272550885, 22.440, 29.0
59.325072016, 22.440, 28.0
59.377593147, 22.440, 24.0
59.430114277, 22.440, 23.0
59.482635408, 22.440, 19.0
59.535156539, 22.440, 28.0
59.587677670, 22.440, 23.0
59.640198800, 22.440, 27.0
59.692719931, 22.440, 26.0
59.745241062, 22.440, 19.0
59.797762192, 22.440, 31.0
59.850283323, 22.440, 35.0
59.902804454, 22.440, 21.0
59.955325585, 22.440, 28.0
60.007846715, 22.440, 32.0
60.060367846, 22.440, 30.0
60.112888977, 22.440, 21.0
60.165410107, 22.440, 26.0
60.217931238, 22.440, 30.0
60.270452369, 22.440, 23.0
60.322973499, 22.440, 28.0
60.375494630, 22.440, 18.0
60.428015761, 22.440, 29.0
60.480536892, 22.440, 26.0
60.533058022, 22.440, 34.0
60.585579153, 22.440, 12.0
60.638100284, 22.440, 22.0
60.690621414, 22.440, 34.0
60.743142545, 22.440, 29.0
60.795663676, 22.440, 40.0
60.848184807, 22.440, 28.0
60.900705937, 22.440, 26.0
60.953227068, 22.440, 35.0
61.005748199, 22.440, 34.0
61.058269329, 22.440, 26.0
61.110790460, 22.440, 26.0
61.163311591, 22.440, 40.0
61.215832722, 22.440, 26.0
61.268353852, 22.440, 31.0
61.320874983, 22.440, 26.0
61.373396114, 22.440, 22.0
61.425917244, 22.440, 26.0
61.478438375, 22.440, 30.0
61.530959506, 22.440, 25.0
61.583480637, 22.440, 30.0
61.636001767, 22.440, 29.0
61.688522898, 22.440, 36.0
61.741044029, 22.440, 31.0
61.793565159, 22.440, 24.0
61.846086290, 22.440, 23.0
61.898607421, 22.440, 28.0
61.951128551, 22.440, 24.0
62.003649682, 22.440, 20.0
62.056170813, 22.440, 30.0
62.108691944, 22.440, 28.0
62.161213074, 22.440, 25.0
62.213734205, 22.440, 25.0
62.266255336, 22.440, 28.0
62.318776466, 22.440, 27.0
62.371297597, 22.440, 43.0
62.423818728, 22.440, 33.0
62.476339859, 22.440, 35.0
62.528860989, 22.440, 45.0
62.581382120, 22.440, 39.0
62.633903251, 22.440, 33.0
62.686424381, 22.440, 36.0
62.738945512, 22.440, 46.0
62.791466643, 22.440, 61.0
62.843987774, 22.440, 122.0
62.896508904, 22.440, 105.0
62.949030035, 22.440, 52.0
63.001551166, 22.440, 74.0
63.054072296, 22.440, 72.0
63.106593427, 22.440, 56.0
63.159114558, 22.440, 30.0
63.211635689, 22.440, 50.0
63.264156819, 22.440, 29.0
63.316677950, 22.440, 33.0
63.369199081, 22.440, 35.0
63.421720211, 22.440, 29.0
63.474241342, 22.440, 37.0
63.526762473, 22.440, 33.0
63.579283603, 22.440, 38.0
63.631804734, 22.440, 37.0
63.684325865, 22.440, 29.0
63.736846996, 22.440, 27.0
63.789368126, 22.440, 31.0
63.841889257, 22.440, 22.0
63.894410388, 22.440, 45.0
63.946931518, 22.440, 25.0
63.999452649, 22.440, 48.0
64.051973780, 22.440, 40.0
64.104494911, 22.440, 46.0
64.157016041, 22.440, 36.0
64.209537172, 22.440, 31.0
64.262058303, 22.440, 34.0
64.314579433, 22.440, 34.0
64.367100564, 22.440, 45.0
64.419621695, 22.440, 29.0
64.472142826, 22.440, 44.0
64.524663956, 22.440, 43.0
64.577185087, 22.440, 39.0
64.629706218, 22.440, 36.0
64.682227348, 22.440, 41.0
64.734748479, 22.440, 68.0
64.787269610, 22.440, 58.0
64.839790740, 22.440, 73.0
64.892311871, 22.440, 120.0
64.944833002, 22.440, 246.0
64.997354133, 22.440, 546.0
65.049875263, 22.440, 557.0
65.102396394, 22.440, 219.0
65.154917525, 22.440, 230.0
65.207438655, 22.440, 280.0
65.259959786, 22.440, 155.0
65.312480917, 22.440, 76.0
65.365002048, 22.440, 66.0
65.417523178, 22.440, 51.0
65.470044309, 22.440, 44.0
65.522565440, 22.440, 32.0
65.575086570, 22.440, 35.0
65.627607701, 22.440, 46.0
65.680128832, 22.440, 40.0
65.732649963, 22.440, 47.0
65.785171093, 22.440, 40.0
65.837692224, 22.440, 27.0
65.890213355, 22.440, 35.0
65.942734485, 22.440, 34.0
65.995255616, 22.440, 31.0
66.047776747, 22.440, 40.0
66.100297878, 22.440, 28.0
66.152819008, 22.440, 30.0
66.205340139, 22.440, 35.0
66.257861270, 22.440, 41.0
66.310382400, 22.440, 27.0
66.362903531, 22.440, 54.0
66.415424662, 22.440, 32.0
66.467945792, 22.440, 37.0
66.520466923, 22.440, 44.0
66.572988054, 22.440, 38.0
66.625509185, 22.440, 47.0
66.678030315, 22.440, 36.0
66.730551446, 22.440, 51.0
66.783072577, 22.440, 56.0
66.835593707, 22.440, 71.0
66.888114838, 22.440, 85.0
66.940635969, 22.440, 104.0
66.993157100, 22.440, 113.0
67.045678230, 22.440, 226.0
67.098199361, 22.440, 862.0
67.150720492, 22.440, 1587.0
67.203241622, 22.440, 565.0
67.255762753, 22.440, 288.0
67.308283884, 22.440, 931.0
67.360805015, 22.440, 749.0
67.413326145, 22.440, 184.0
67.465847276, 22.440, 79.0
67.518368407, 22.440, 77.0
67.570889537, 22.440, 60.0
67.623410668, 22.440, 46.0
67.675931799, 22.440, 39.0
67.728452930, 22.440, 42.0
67.780974060, 22.440, 37.0
67.833495191, 22.440, 33.0
67.886016322, 22.440, 41.0
67.938537452, 22.440, 40.0
67.991058583, 22.440, 40.0
68.043579714, 22.440, 49.0
68.096100844, 22.440, 33.0
68.148621975, 22.440, 30.0
68.201143106, 22.440, 41.0
68.253664237, 22.440, 32.0
68.306185367, 22.440, 28.0
68.358706498, 22.440, 41.0
68.411227629, 22.440, 42.0
68.463748759, 22.440, 33.0
68.516269890, 22.440, 35.0
68.568791021, 22.440, 40.0
68.621312152, 22.440, 34.0
68.673833282, 22.440, 33.0
68.726354413, 22.440, 38.0
68.778875544, 22.440, 26.0
68.831396674, 22.440, 31.0
68.883917805, 22.440, 36.0
68.936438936, 22.440, 35.0
68.988960067, 22.440, 38.0
69.041481197, 22.440, 28.0
69.094002328, 22.440, 43.0
69.146523459, 22.440, 55.0
69.199044589, 22.440, 56.0
69.251565720, 22.440, 57.0
69.304086851, 22.440, 55.0
69.356607981, 22.440, 42.0
69.409129112, 22.440, 44.0
69.461650243, 22.440, 35.0
69.514171374, 22.440, 43.0
69.566692504, 22.440, 37.0
69.619213635, 22.440, 29.0
69.671734766, 22.440, 32.0
69.724255896, 22.440, 41.0
69.776777027, 22.440, 28.0
69.829298158, 22.440, 33.0
69.881819289, 22.440, 38.0
69.934340419, 22.440, 38.0
69.986861550, 22.440, 32.0